Workbook
Name list: #REF!

Sheet Bendra įskaita
C1: Oficialus TRItono klubo reitingas
A3: Nr. | B3: +/- | C3: Dalyvis | D3: 2024 05 17 PANEVĖŽYS | E3: 2025 06 01 KAIŠIADORYS | F3: 2026 06 14 VEISIEJAI | G3: 2026 06 20 GDANSKAS | H3: 2026 06 28 TRAKAI | I3: 2026 07 19 JONAVA | J3: 2027 08 01 PANEVĖŽYS | K3: 2026 08 16 SKAUDVILĖ | L3: 2026 08 23 MOLĖTAI | M3: 2026 09 05 DRUSKININKAI | N3: Varžybų skaičius | O3: Visų taškų suma | P3: Taškų vidurkis | Q3: 3 geriausių rezultatų suma | R3: 2025 Vieta | S3: 2025 Varžybų | T3: 2024 Vieta | U3: 2024 Varžybų
A4: 1 | B4: =Table_1[[#This Row],[2025 Vieta]]-A4 -> 0 | C4: Mantas Jablonskis | D4: {=IFERROR(INDEX(Panevezys!P:P,MATCH(C4,Panevezys!E:E,0),0),"")} -> 900 | E4: {=IFERROR(INDEX(Kaisiadorys!Q:Q,MATCH(C4,Kaisiadorys!E:E,0),0),"")} | F4: {=IFERROR(INDEX(Veisiejai!Q:Q,MATCH(C4,Veisiejai!E:E,0),0),"")} -> 969 | G4: {=IFERROR(INDEX(Gdanskas!P:P,MATCH(C4,Gdanskas!C:C,0),0),"")} | H4: {=IFERROR(INDEX(Trakai!R:R,MATCH(C4,Trakai!E:E,0),0),"")} -> 1000 | I4: {=IFERROR(INDEX(Jonava!Q:Q,MATCH(C4,Jonava!E:E,0),0),"")} -> 1000 | J4: {=IFERROR(INDEX(Panevezys2!R:R,MATCH(C4,Panevezys2!E:E,0),0),"")} -> 1100 | K4: =IFERROR(INDEX(Skaudvile!Q:Q,MATCH(C4,Skaudvile!E:E,0),0),"") -> 1000 | L4: =IFERROR(INDEX(Moletai!Q:Q,MATCH(C4,Moletai!E:E,0),0),"") -> 1000 | N4: =COUNTIF(D4:M4,">0") -> 7 | O4: =SUM(D4:M4) -> 6969 | P4: =O4/N4 -> 995.57143 | Q4: {=IFERROR(SUMPRODUCT(LARGE(D4:M4,{1;2;3})),"0")} -> 3100 | R4: =IFERROR(INDEX('Bendra įskaita (2025)'!A:A,MATCH(C4,'Bendra įskaita (2025)'!B:B,0),0),"") -> 1 | S4: =IFERROR(INDEX('Bendra įskaita (2025)'!K:K,MATCH(C4,'Bendra įskaita (2025)'!B:B,0),0),"") -> 5 | T4: =IFERROR(INDEX('Bendra įskaita (2024)'!A:A,MATCH(C4,'Bendra įskaita (2024)'!B:B,0),0),"") -> 1 | U4: =IFERROR(INDEX('Bendra įskaita (2024)'!L:L,MATCH(C4,'Bendra įskaita (2024)'!B:B,0),0),"") -> 8
A5: 2 | B5: NEW | C5: Radoslav Lajevski | D5: {=IFERROR(INDEX(Panevezys!P:P,MATCH(C5,Panevezys!E:E,0),0),"")} | E5: {=IFERROR(INDEX(Kaisiadorys!Q:Q,MATCH(C5,Kaisiadorys!E:E,0),0),"")} -> 963 | F5: {=IFERROR(INDEX(Veisiejai!Q:Q,MATCH(C5,Veisiejai!E:E,0),0),"")} | G5: {=IFERROR(INDEX(Gdanskas!P:P,MATCH(C5,Gdanskas!C:C,0),0),"")} | H5: {=IFERROR(INDEX(Trakai!R:R,MATCH(C5,Trakai!E:E,0),0),"")} -> 956 | I5: {=IFERROR(INDEX(Jonava!Q:Q,MATCH(C5,Jonava!E:E,0),0),"")} -> 935 | J5: {=IFERROR(INDEX(Panevezys2!R:R,MATCH(C5,Panevezys2!E:E,0),0),"")} -> 1072 | K5: =IFERROR(INDEX(Skaudvile!Q:Q,MATCH(C5,Skaudvile!E:E,0),0),"") | L5: =IFERROR(INDEX(Moletai!Q:Q,MATCH(C5,Moletai!E:E,0),0),"") | N5: =COUNTIF(D5:M5,">0") -> 4 | O5: =SUM(D5:M5) -> 3926 | P5: =O5/N5 -> 981.5 | Q5: {=IFERROR(SUMPRODUCT(LARGE(D5:M5,{1;2;3})),"0")} -> 2991 | R5: =IFERROR(INDEX('Bendra įskaita (2025)'!A:A,MATCH(C5,'Bendra įskaita (2025)'!B:B,0),0),"") | S5: =IFERROR(INDEX('Bendra įskaita (2025)'!K:K,MATCH(C5,'Bendra įskaita (2025)'!B:B,0),0),"") | T5: =IFERROR(INDEX('Bendra įskaita (2024)'!A:A,MATCH(C5,'Bendra įskaita (2024)'!B:B,0),0),"") | U5: =IFERROR(INDEX('Bendra įskaita (2024)'!L:L,MATCH(C5,'Bendra įskaita (2024)'!B:B,0),0),"")
A6: 3 | B6: =Table_1[[#This Row],[2025 Vieta]]-A6 -> 0 | C6: Airidas Gražinskis | D6: {=IFERROR(INDEX(Panevezys!P:P,MATCH(C6,Panevezys!E:E,0),0),"")} | E6: {=IFERROR(INDEX(Kaisiadorys!Q:Q,MATCH(C6,Kaisiadorys!E:E,0),0),"")} -> 931 | F6: {=IFERROR(INDEX(Veisiejai!Q:Q,MATCH(C6,Veisiejai!E:E,0),0),"")} | G6: {=IFERROR(INDEX(Gdanskas!P:P,MATCH(C6,Gdanskas!C:C,0),0),"")} -> 999 | H6: {=IFERROR(INDEX(Trakai!R:R,MATCH(C6,Trakai!E:E,0),0),"")} -> 948 | I6: {=IFERROR(INDEX(Jonava!Q:Q,MATCH(C6,Jonava!E:E,0),0),"")} -> 927 | J6: {=IFERROR(INDEX(Panevezys2!R:R,MATCH(C6,Panevezys2!E:E,0),0),"")} -> 1033 | K6: =IFERROR(INDEX(Skaudvile!Q:Q,MATCH(C6,Skaudvile!E:E,0),0),"") | L6: =IFERROR(INDEX(Moletai!Q:Q,MATCH(C6,Moletai!E:E,0),0),"") | N6: =COUNTIF(D6:M6,">0") -> 5 | O6: =SUM(D6:M6) -> 4838 | P6: =O6/N6 -> 967.6 | Q6: {=IFERROR(SUMPRODUCT(LARGE(D6:M6,{1;2;3})),"0")} -> 2980 | R6: =IFERROR(INDEX('Bendra įskaita (2025)'!A:A,MATCH(C6,'Bendra įskaita (2025)'!B:B,0),0),"") -> 3 | S6: =IFERROR(INDEX('Bendra įskaita (2025)'!K:K,MATCH(C6,'Bendra įskaita (2025)'!B:B,0),0),"") -> 3 | T6: =IFERROR(INDEX('Bendra įskaita (2024)'!A:A,MATCH(C6,'Bendra įskaita (2024)'!B:B,0),0),"") -> 2 | U6: =IFERROR(INDEX('Bendra įskaita (2024)'!L:L,MATCH(C6,'Bendra įskaita (2024)'!B:B,0),0),"") -> 8
A7: 4 | B7: =Table_1[[#This Row],[2025 Vieta]]-A7 -> 6 | C7: Lukas Matulaitis | D7: {=IFERROR(INDEX(Panevezys!P:P,MATCH(C7,Panevezys!E:E,0),0),"")} -> 793 | E7: {=IFERROR(INDEX(Kaisiadorys!Q:Q,MATCH(C7,Kaisiadorys!E:E,0),0),"")} | F7: {=IFERROR(INDEX(Veisiejai!Q:Q,MATCH(C7,Veisiejai!E:E,0),0),"")} | G7: {=IFERROR(INDEX(Gdanskas!P:P,MATCH(C7,Gdanskas!C:C,0),0),"")} -> 950 | H7: {=IFERROR(INDEX(Trakai!R:R,MATCH(C7,Trakai!E:E,0),0),"")} -> 901 | I7: {=IFERROR(INDEX(Jonava!Q:Q,MATCH(C7,Jonava!E:E,0),0),"")} | J7: {=IFERROR(INDEX(Panevezys2!R:R,MATCH(C7,Panevezys2!E:E,0),0),"")} -> 973 | K7: =IFERROR(INDEX(Skaudvile!Q:Q,MATCH(C7,Skaudvile!E:E,0),0),"") | L7: =IFERROR(INDEX(Moletai!Q:Q,MATCH(C7,Moletai!E:E,0),0),"") -> 878 | N7: =COUNTIF(D7:M7,">0") -> 5 | O7: =SUM(D7:M7) -> 4495 | P7: =O7/N7 -> 899 | Q7: {=IFERROR(SUMPRODUCT(LARGE(D7:M7,{1;2;3})),"0")} -> 2824 | R7: =IFERROR(INDEX('Bendra įskaita (2025)'!A:A,MATCH(C7,'Bendra įskaita (2025)'!B:B,0),0),"") -> 10 | S7: =IFERROR(INDEX('Bendra įskaita (2025)'!K:K,MATCH(C7,'Bendra įskaita (2025)'!B:B,0),0),"") -> 3 | T7: =IFERROR(INDEX('Bendra įskaita (2024)'!A:A,MATCH(C7,'Bendra įskaita (2024)'!B:B,0),0),"") -> 8 | U7: =IFERROR(INDEX('Bendra įskaita (2024)'!L:L,MATCH(C7,'Bendra įskaita (2024)'!B:B,0),0),"") -> 3
A8: 5 | B8: =Table_1[[#This Row],[2025 Vieta]]-A8 -> 18 | C8: Mantas Kukenys | D8: {=IFERROR(INDEX(Panevezys!P:P,MATCH(C8,Panevezys!E:E,0),0),"")} | E8: {=IFERROR(INDEX(Kaisiadorys!Q:Q,MATCH(C8,Kaisiadorys!E:E,0),0),"")} -> 873 | F8: {=IFERROR(INDEX(Veisiejai!Q:Q,MATCH(C8,Veisiejai!E:E,0),0),"")} | G8: {=IFERROR(INDEX(Gdanskas!P:P,MATCH(C8,Gdanskas!C:C,0),0),"")} -> 920 | H8: {=IFERROR(INDEX(Trakai!R:R,MATCH(C8,Trakai!E:E,0),0),"")} -> 833 | I8: {=IFERROR(INDEX(Jonava!Q:Q,MATCH(C8,Jonava!E:E,0),0),"")} -> 868 | J8: {=IFERROR(INDEX(Panevezys2!R:R,MATCH(C8,Panevezys2!E:E,0),0),"")} -> 906 | K8: =IFERROR(INDEX(Skaudvile!Q:Q,MATCH(C8,Skaudvile!E:E,0),0),"") | L8: =IFERROR(INDEX(Moletai!Q:Q,MATCH(C8,Moletai!E:E,0),0),"") -> 857 | N8: =COUNTIF(D8:M8,">0") -> 6 | O8: =SUM(D8:M8) -> 5257 | P8: =O8/N8 -> 876.16667 | Q8: {=IFERROR(SUMPRODUCT(LARGE(D8:M8,{1;2;3})),"0")} -> 2699 | R8: =IFERROR(INDEX('Bendra įskaita (2025)'!A:A,MATCH(C8,'Bendra įskaita (2025)'!B:B,0),0),"") -> 23 | S8: =IFERROR(INDEX('Bendra įskaita (2025)'!K:K,MATCH(C8,'Bendra įskaita (2025)'!B:B,0),0),"") -> 2 | T8: =IFERROR(INDEX('Bendra įskaita (2024)'!A:A,MATCH(C8,'Bendra įskaita (2024)'!B:B,0),0),"") -> 7 | U8: =IFERROR(INDEX('Bendra įskaita (2024)'!L:L,MATCH(C8,'Bendra įskaita (2024)'!B:B,0),0),"") -> 4
A9: 6 | B9: =Table_1[[#This Row],[2025 Vieta]]-A9 -> 5 | C9: Darius Borisas | D9: {=IFERROR(INDEX(Panevezys!P:P,MATCH(C9,Panevezys!E:E,0),0),"")} -> 756 | E9: {=IFERROR(INDEX(Kaisiadorys!Q:Q,MATCH(C9,Kaisiadorys!E:E,0),0),"")} -> 801 | F9: {=IFERROR(INDEX(Veisiejai!Q:Q,MATCH(C9,Veisiejai!E:E,0),0),"")} | G9: {=IFERROR(INDEX(Gdanskas!P:P,MATCH(C9,Gdanskas!C:C,0),0),"")} -> 873 | H9: {=IFERROR(INDEX(Trakai!R:R,MATCH(C9,Trakai!E:E,0),0),"")} | I9: {=IFERROR(INDEX(Jonava!Q:Q,MATCH(C9,Jonava!E:E,0),0),"")} -> 809 | J9: {=IFERROR(INDEX(Panevezys2!R:R,MATCH(C9,Panevezys2!E:E,0),0),"")} -> 927 | K9: =IFERROR(INDEX(Skaudvile!Q:Q,MATCH(C9,Skaudvile!E:E,0),0),"") -> 840 | L9: =IFERROR(INDEX(Moletai!Q:Q,MATCH(C9,Moletai!E:E,0),0),"") -> 844 | N9: =COUNTIF(D9:M9,">0") -> 7 | O9: =SUM(D9:M9) -> 5850 | P9: =O9/N9 -> 835.71429 | Q9: {=IFERROR(SUMPRODUCT(LARGE(D9:M9,{1;2;3})),"0")} -> 2644 | R9: =IFERROR(INDEX('Bendra įskaita (2025)'!A:A,MATCH(C9,'Bendra įskaita (2025)'!B:B,0),0),"") -> 11 | S9: =IFERROR(INDEX('Bendra įskaita (2025)'!K:K,MATCH(C9,'Bendra įskaita (2025)'!B:B,0),0),"") -> 4 | T9: =IFERROR(INDEX('Bendra įskaita (2024)'!A:A,MATCH(C9,'Bendra įskaita (2024)'!B:B,0),0),"") -> 17 | U9: =IFERROR(INDEX('Bendra įskaita (2024)'!L:L,MATCH(C9,'Bendra įskaita (2024)'!B:B,0),0),"") -> 4
A10: 7 | B10: =Table_1[[#This Row],[2025 Vieta]]-A10 -> 5 | C10: Vaidas Velutis | D10: {=IFERROR(INDEX(Panevezys!P:P,MATCH(C10,Panevezys!E:E,0),0),"")} | E10: {=IFERROR(INDEX(Kaisiadorys!Q:Q,MATCH(C10,Kaisiadorys!E:E,0),0),"")} -> 837 | F10: {=IFERROR(INDEX(Veisiejai!Q:Q,MATCH(C10,Veisiejai!E:E,0),0),"")} -> 804 | G10: {=IFERROR(INDEX(Gdanskas!P:P,MATCH(C10,Gdanskas!C:C,0),0),"")} -> 883 | H10: {=IFERROR(INDEX(Trakai!R:R,MATCH(C10,Trakai!E:E,0),0),"")} | I10: {=IFERROR(INDEX(Jonava!Q:Q,MATCH(C10,Jonava!E:E,0),0),"")} | J10: {=IFERROR(INDEX(Panevezys2!R:R,MATCH(C10,Panevezys2!E:E,0),0),"")} -> 923 | K10: =IFERROR(INDEX(Skaudvile!Q:Q,MATCH(C10,Skaudvile!E:E,0),0),"") | L10: =IFERROR(INDEX(Moletai!Q:Q,MATCH(C10,Moletai!E:E,0),0),"") | N10: =COUNTIF(D10:M10,">0") -> 4 | O10: =SUM(D10:M10) -> 3447 | P10: =O10/N10 -> 861.75 | Q10: {=IFERROR(SUMPRODUCT(LARGE(D10:M10,{1;2;3})),"0")} -> 2643 | R10: =IFERROR(INDEX('Bendra įskaita (2025)'!A:A,MATCH(C10,'Bendra įskaita (2025)'!B:B,0),0),"") -> 12 | S10: =IFERROR(INDEX('Bendra įskaita (2025)'!K:K,MATCH(C10,'Bendra įskaita (2025)'!B:B,0),0),"") -> 3 | T10: =IFERROR(INDEX('Bendra įskaita (2024)'!A:A,MATCH(C10,'Bendra įskaita (2024)'!B:B,0),0),"") -> 35 | U10: =IFERROR(INDEX('Bendra įskaita (2024)'!L:L,MATCH(C10,'Bendra įskaita (2024)'!B:B,0),0),"") -> 1
A11: 8 | B11: =Table_1[[#This Row],[2025 Vieta]]-A11 -> -3 | C11: Mantas Marcinkevičius | D11: {=IFERROR(INDEX(Panevezys!P:P,MATCH(C11,Panevezys!E:E,0),0),"")} -> 828 | E11: {=IFERROR(INDEX(Kaisiadorys!Q:Q,MATCH(C11,Kaisiadorys!E:E,0),0),"")} | F11: {=IFERROR(INDEX(Veisiejai!Q:Q,MATCH(C11,Veisiejai!E:E,0),0),"")} -> 863 | G11: {=IFERROR(INDEX(Gdanskas!P:P,MATCH(C11,Gdanskas!C:C,0),0),"")} -> 922 | H11: {=IFERROR(INDEX(Trakai!R:R,MATCH(C11,Trakai!E:E,0),0),"")} -> 846 | I11: {=IFERROR(INDEX(Jonava!Q:Q,MATCH(C11,Jonava!E:E,0),0),"")} -> 853 | J11: {=IFERROR(INDEX(Panevezys2!R:R,MATCH(C11,Panevezys2!E:E,0),0),"")} | K11: =IFERROR(INDEX(Skaudvile!Q:Q,MATCH(C11,Skaudvile!E:E,0),0),"") | L11: =IFERROR(INDEX(Moletai!Q:Q,MATCH(C11,Moletai!E:E,0),0),"") -> 851 | N11: =COUNTIF(D11:M11,">0") -> 6 | O11: =SUM(D11:M11) -> 5163 | P11: =O11/N11 -> 860.5 | Q11: {=IFERROR(SUMPRODUCT(LARGE(D11:M11,{1;2;3})),"0")} -> 2638 | R11: =IFERROR(INDEX('Bendra įskaita (2025)'!A:A,MATCH(C11,'Bendra įskaita (2025)'!B:B,0),0),"") -> 5 | S11: =IFERROR(INDEX('Bendra įskaita (2025)'!K:K,MATCH(C11,'Bendra įskaita (2025)'!B:B,0),0),"") -> 4 | T11: =IFERROR(INDEX('Bendra įskaita (2024)'!A:A,MATCH(C11,'Bendra įskaita (2024)'!B:B,0),0),"") -> 10 | U11: =IFERROR(INDEX('Bendra įskaita (2024)'!L:L,MATCH(C11,'Bendra įskaita (2024)'!B:B,0),0),"") -> 4
A12: 9 | B12: =Table_1[[#This Row],[2025 Vieta]]-A12 -> -1 | C12: Arvydas Sereičikas | D12: {=IFERROR(INDEX(Panevezys!P:P,MATCH(C12,Panevezys!E:E,0),0),"")} -> 758 | E12: {=IFERROR(INDEX(Kaisiadorys!Q:Q,MATCH(C12,Kaisiadorys!E:E,0),0),"")} -> 836 | F12: {=IFERROR(INDEX(Veisiejai!Q:Q,MATCH(C12,Veisiejai!E:E,0),0),"")} -> 837 | G12: {=IFERROR(INDEX(Gdanskas!P:P,MATCH(C12,Gdanskas!C:C,0),0),"")} | H12: {=IFERROR(INDEX(Trakai!R:R,MATCH(C12,Trakai!E:E,0),0),"")} -> 829 | I12: {=IFERROR(INDEX(Jonava!Q:Q,MATCH(C12,Jonava!E:E,0),0),"")} -> 814 | J12: {=IFERROR(INDEX(Panevezys2!R:R,MATCH(C12,Panevezys2!E:E,0),0),"")} -> 913 | K12: =IFERROR(INDEX(Skaudvile!Q:Q,MATCH(C12,Skaudvile!E:E,0),0),"") | L12: =IFERROR(INDEX(Moletai!Q:Q,MATCH(C12,Moletai!E:E,0),0),"") | N12: =COUNTIF(D12:M12,">0") -> 6 | O12: =SUM(D12:M12) -> 4987 | P12: =O12/N12 -> 831.16667 | Q12: {=IFERROR(SUMPRODUCT(LARGE(D12:M12,{1;2;3})),"0")} -> 2586 | R12: =IFERROR(INDEX('Bendra įskaita (2025)'!A:A,MATCH(C12,'Bendra įskaita (2025)'!B:B,0),0),"") -> 8 | S12: =IFERROR(INDEX('Bendra įskaita (2025)'!K:K,MATCH(C12,'Bendra įskaita (2025)'!B:B,0),0),"") -> 5 | T12: =IFERROR(INDEX('Bendra įskaita (2024)'!A:A,MATCH(C12,'Bendra įskaita (2024)'!B:B,0),0),"") | U12: =IFERROR(INDEX('Bendra įskaita (2024)'!L:L,MATCH(C12,'Bendra įskaita (2024)'!B:B,0),0),"")
A13: 10 | B13: =Table_1[[#This Row],[2025 Vieta]]-A13 -> -8 | C13: Arvydas Gervelė | D13: {=IFERROR(INDEX(Panevezys!P:P,MATCH(C13,Panevezys!E:E,0),0),"")} | E13: {=IFERROR(INDEX(Kaisiadorys!Q:Q,MATCH(C13,Kaisiadorys!E:E,0),0),"")} -> 862 | F13: {=IFERROR(INDEX(Veisiejai!Q:Q,MATCH(C13,Veisiejai!E:E,0),0),"")} -> 859 | G13: {=IFERROR(INDEX(Gdanskas!P:P,MATCH(C13,Gdanskas!C:C,0),0),"")} | H13: {=IFERROR(INDEX(Trakai!R:R,MATCH(C13,Trakai!E:E,0),0),"")} | I13: {=IFERROR(INDEX(Jonava!Q:Q,MATCH(C13,Jonava!E:E,0),0),"")} -> 848 | J13: {=IFERROR(INDEX(Panevezys2!R:R,MATCH(C13,Panevezys2!E:E,0),0),"")} | K13: =IFERROR(INDEX(Skaudvile!Q:Q,MATCH(C13,Skaudvile!E:E,0),0),"") | L13: =IFERROR(INDEX(Moletai!Q:Q,MATCH(C13,Moletai!E:E,0),0),"") -> 844 | N13: =COUNTIF(D13:M13,">0") -> 4 | O13: =SUM(D13:M13) -> 3413 | P13: =O13/N13 -> 853.25 | Q13: {=IFERROR(SUMPRODUCT(LARGE(D13:M13,{1;2;3})),"0")} -> 2569 | R13: =IFERROR(INDEX('Bendra įskaita (2025)'!A:A,MATCH(C13,'Bendra įskaita (2025)'!B:B,0),0),"") -> 2 | S13: =IFERROR(INDEX('Bendra įskaita (2025)'!K:K,MATCH(C13,'Bendra įskaita (2025)'!B:B,0),0),"") -> 4 | T13: =IFERROR(INDEX('Bendra įskaita (2024)'!A:A,MATCH(C13,'Bendra įskaita (2024)'!B:B,0),0),"") -> 31 | U13: =IFERROR(INDEX('Bendra įskaita (2024)'!L:L,MATCH(C13,'Bendra įskaita (2024)'!B:B,0),0),"") -> 1
A14: 11 | B14: =Table_1[[#This Row],[2025 Vieta]]-A14 -> -7 | C14: Raimondas Gincas | D14: {=IFERROR(INDEX(Panevezys!P:P,MATCH(C14,Panevezys!E:E,0),0),"")} | E14: {=IFERROR(INDEX(Kaisiadorys!Q:Q,MATCH(C14,Kaisiadorys!E:E,0),0),"")} -> 850 | F14: {=IFERROR(INDEX(Veisiejai!Q:Q,MATCH(C14,Veisiejai!E:E,0),0),"")} -> 864 | G14: {=IFERROR(INDEX(Gdanskas!P:P,MATCH(C14,Gdanskas!C:C,0),0),"")} | H14: {=IFERROR(INDEX(Trakai!R:R,MATCH(C14,Trakai!E:E,0),0),"")} -> 809 | I14: {=IFERROR(INDEX(Jonava!Q:Q,MATCH(C14,Jonava!E:E,0),0),"")} -> 854 | J14: {=IFERROR(INDEX(Panevezys2!R:R,MATCH(C14,Panevezys2!E:E,0),0),"")} | K14: =IFERROR(INDEX(Skaudvile!Q:Q,MATCH(C14,Skaudvile!E:E,0),0),"") | L14: =IFERROR(INDEX(Moletai!Q:Q,MATCH(C14,Moletai!E:E,0),0),"") | N14: =COUNTIF(D14:M14,">0") -> 4 | O14: =SUM(D14:M14) -> 3377 | P14: =O14/N14 -> 844.25 | Q14: {=IFERROR(SUMPRODUCT(LARGE(D14:M14,{1;2;3})),"0")} -> 2568 | R14: =IFERROR(INDEX('Bendra įskaita (2025)'!A:A,MATCH(C14,'Bendra įskaita (2025)'!B:B,0),0),"") -> 4 | S14: =IFERROR(INDEX('Bendra įskaita (2025)'!K:K,MATCH(C14,'Bendra įskaita (2025)'!B:B,0),0),"") -> 6 | T14: =IFERROR(INDEX('Bendra įskaita (2024)'!A:A,MATCH(C14,'Bendra įskaita (2024)'!B:B,0),0),"") -> 12 | U14: =IFERROR(INDEX('Bendra įskaita (2024)'!L:L,MATCH(C14,'Bendra įskaita (2024)'!B:B,0),0),"") -> 5
A15: 12 | B15: =Table_1[[#This Row],[2025 Vieta]]-A15 -> 1 | C15: Saulius Kerza | D15: {=IFERROR(INDEX(Panevezys!P:P,MATCH(C15,Panevezys!E:E,0),0),"")} -> 742 | E15: {=IFERROR(INDEX(Kaisiadorys!Q:Q,MATCH(C15,Kaisiadorys!E:E,0),0),"")} -> 828 | F15: {=IFERROR(INDEX(Veisiejai!Q:Q,MATCH(C15,Veisiejai!E:E,0),0),"")} -> 813 | G15: {=IFERROR(INDEX(Gdanskas!P:P,MATCH(C15,Gdanskas!C:C,0),0),"")} -> 829 | H15: {=IFERROR(INDEX(Trakai!R:R,MATCH(C15,Trakai!E:E,0),0),"")} | I15: {=IFERROR(INDEX(Jonava!Q:Q,MATCH(C15,Jonava!E:E,0),0),"")} -> 810 | J15: {=IFERROR(INDEX(Panevezys2!R:R,MATCH(C15,Panevezys2!E:E,0),0),"")} -> 878 | K15: =IFERROR(INDEX(Skaudvile!Q:Q,MATCH(C15,Skaudvile!E:E,0),0),"") | L15: =IFERROR(INDEX(Moletai!Q:Q,MATCH(C15,Moletai!E:E,0),0),"") -> 818 | N15: =COUNTIF(D15:M15,">0") -> 7 | O15: =SUM(D15:M15) -> 5718 | P15: =O15/N15 -> 816.85714 | Q15: {=IFERROR(SUMPRODUCT(LARGE(D15:M15,{1;2;3})),"0")} -> 2535 | R15: =IFERROR(INDEX('Bendra įskaita (2025)'!A:A,MATCH(C15,'Bendra įskaita (2025)'!B:B,0),0),"") -> 13 | S15: =IFERROR(INDEX('Bendra įskaita (2025)'!K:K,MATCH(C15,'Bendra įskaita (2025)'!B:B,0),0),"") -> 3 | T15: =IFERROR(INDEX('Bendra įskaita (2024)'!A:A,MATCH(C15,'Bendra įskaita (2024)'!B:B,0),0),"") -> 15 | U15: =IFERROR(INDEX('Bendra įskaita (2024)'!L:L,MATCH(C15,'Bendra įskaita (2024)'!B:B,0),0),"") -> 5
A16: 13 | B16: =Table_1[[#This Row],[2025 Vieta]]-A16 -> -4 | C16: Arūnas Maciulevičius | D16: {=IFERROR(INDEX(Panevezys!P:P,MATCH(C16,Panevezys!E:E,0),0),"")} -> 700 | E16: {=IFERROR(INDEX(Kaisiadorys!Q:Q,MATCH(C16,Kaisiadorys!E:E,0),0),"")} -> 763 | F16: {=IFERROR(INDEX(Veisiejai!Q:Q,MATCH(C16,Veisiejai!E:E,0),0),"")} -> 745 | G16: {=IFERROR(INDEX(Gdanskas!P:P,MATCH(C16,Gdanskas!C:C,0),0),"")} -> 786 | H16: {=IFERROR(INDEX(Trakai!R:R,MATCH(C16,Trakai!E:E,0),0),"")} -> 797 | I16: {=IFERROR(INDEX(Jonava!Q:Q,MATCH(C16,Jonava!E:E,0),0),"")} -> 771 | J16: {=IFERROR(INDEX(Panevezys2!R:R,MATCH(C16,Panevezys2!E:E,0),0),"")} -> 843 | K16: =IFERROR(INDEX(Skaudvile!Q:Q,MATCH(C16,Skaudvile!E:E,0),0),"") -> 770 | L16: =IFERROR(INDEX(Moletai!Q:Q,MATCH(C16,Moletai!E:E,0),0),"") | N16: =COUNTIF(D16:M16,">0") -> 8 | O16: =SUM(D16:M16) -> 6175 | P16: =O16/N16 -> 771.875 | Q16: {=IFERROR(SUMPRODUCT(LARGE(D16:M16,{1;2;3})),"0")} -> 2426 | R16: =IFERROR(INDEX('Bendra įskaita (2025)'!A:A,MATCH(C16,'Bendra įskaita (2025)'!B:B,0),0),"") -> 9 | S16: =IFERROR(INDEX('Bendra įskaita (2025)'!K:K,MATCH(C16,'Bendra įskaita (2025)'!B:B,0),0),"") -> 8 | T16: =IFERROR(INDEX('Bendra įskaita (2024)'!A:A,MATCH(C16,'Bendra įskaita (2024)'!B:B,0),0),"") -> 14 | U16: =IFERROR(INDEX('Bendra įskaita (2024)'!L:L,MATCH(C16,'Bendra įskaita (2024)'!B:B,0),0),"") -> 6
A17: 14 | B17: =Table_1[[#This Row],[2025 Vieta]]-A17 -> 12 | C17: Juozas Karmaza | D17: {=IFERROR(INDEX(Panevezys!P:P,MATCH(C17,Panevezys!E:E,0),0),"")} | E17: {=IFERROR(INDEX(Kaisiadorys!Q:Q,MATCH(C17,Kaisiadorys!E:E,0),0),"")} -> 780 | F17: {=IFERROR(INDEX(Veisiejai!Q:Q,MATCH(C17,Veisiejai!E:E,0),0),"")} -> 784 | G17: {=IFERROR(INDEX(Gdanskas!P:P,MATCH(C17,Gdanskas!C:C,0),0),"")} | H17: {=IFERROR(INDEX(Trakai!R:R,MATCH(C17,Trakai!E:E,0),0),"")} -> 825 | I17: {=IFERROR(INDEX(Jonava!Q:Q,MATCH(C17,Jonava!E:E,0),0),"")} | J17: {=IFERROR(INDEX(Panevezys2!R:R,MATCH(C17,Panevezys2!E:E,0),0),"")} | K17: =IFERROR(INDEX(Skaudvile!Q:Q,MATCH(C17,Skaudvile!E:E,0),0),"") | L17: =IFERROR(INDEX(Moletai!Q:Q,MATCH(C17,Moletai!E:E,0),0),"") | N17: =COUNTIF(D17:M17,">0") -> 3 | O17: =SUM(D17:M17) -> 2389 | P17: =O17/N17 -> 796.33333 | Q17: {=IFERROR(SUMPRODUCT(LARGE(D17:M17,{1;2;3})),"0")} -> 2389 | R17: =IFERROR(INDEX('Bendra įskaita (2025)'!A:A,MATCH(C17,'Bendra įskaita (2025)'!B:B,0),0),"") -> 26 | S17: =IFERROR(INDEX('Bendra įskaita (2025)'!K:K,MATCH(C17,'Bendra įskaita (2025)'!B:B,0),0),"") -> 2 | T17: =IFERROR(INDEX('Bendra įskaita (2024)'!A:A,MATCH(C17,'Bendra įskaita (2024)'!B:B,0),0),"") | U17: =IFERROR(INDEX('Bendra įskaita (2024)'!L:L,MATCH(C17,'Bendra įskaita (2024)'!B:B,0),0),"")
... A21: 18 | B21: =Table_1[[#This Row],[2025 Vieta]]-A21 -> 2 | C21: Jūratė Keinytė | D21: {=IFERROR(INDEX(Panevezys!P:P,MATCH(C21,Panevezys!E:E,0),0),"")} | E21: {=IFERROR(INDEX(Kaisiadorys!Q:Q,MATCH(C21,Kaisiadorys!E:E,0),0),"")} -> 689 | F21: {=IFERROR(INDEX(Veisiejai!Q:Q,MATCH(C21,Veisiejai!E:E,0),0),"")} -> 687 | G21: {=IFERROR(INDEX(Gdanskas!P:P,MATCH(C21,Gdanskas!C:C,0),0),"")} -> 744 | H21: {=IFERROR(INDEX(Trakai!R:R,MATCH(C21,Trakai!E:E,0),0),"")} | I21: {=IFERROR(INDEX(Jonava!Q:Q,MATCH(C21,Jonava!E:E,0),0),"")} -> 688 | J21: {=IFERROR(INDEX(Panevezys2!R:R,MATCH(C21,Panevezys2!E:E,0),0),"")} | K21: =IFERROR(INDEX(Skaudvile!Q:Q,MATCH(C21,Skaudvile!E:E,0),0),"") | L21: =IFERROR(INDEX(Moletai!Q:Q,MATCH(C21,Moletai!E:E,0),0),"") -> 701 | N21: =COUNTIF(D21:M21,">0") -> 5 | O21: =SUM(D21:M21) -> 3509 | P21: =O21/N21 -> 701.8 | Q21: {=IFERROR(SUMPRODUCT(LARGE(D21:M21,{1;2;3})),"0")} -> 2134 | R21: =IFERROR(INDEX('Bendra įskaita (2025)'!A:A,MATCH(C21,'Bendra įskaita (2025)'!B:B,0),0),"") -> 20 | S21: =IFERROR(INDEX('Bendra įskaita (2025)'!K:K,MATCH(C21,'Bendra įskaita (2025)'!B:B,0),0),"") -> 3 | T21: =IFERROR(INDEX('Bendra įskaita (2024)'!A:A,MATCH(C21,'Bendra įskaita (2024)'!B:B,0),0),"") | U21: =IFERROR(INDEX('Bendra įskaita (2024)'!L:L,MATCH(C21,'Bendra įskaita (2024)'!B:B,0),0),"")
A22: 19 | B22: NEW | C22: Ruslanas Kryžanauskas | D22: {=IFERROR(INDEX(Panevezys!P:P,MATCH(C22,Panevezys!E:E,0),0),"")} | E22: {=IFERROR(INDEX(Kaisiadorys!Q:Q,MATCH(C22,Kaisiadorys!E:E,0),0),"")} | F22: {=IFERROR(INDEX(Veisiejai!Q:Q,MATCH(C22,Veisiejai!E:E,0),0),"")} | G22: {=IFERROR(INDEX(Gdanskas!P:P,MATCH(C22,Gdanskas!C:C,0),0),"")} | H22: {=IFERROR(INDEX(Trakai!R:R,MATCH(C22,Trakai!E:E,0),0),"")} -> 655 | I22: {=IFERROR(INDEX(Jonava!Q:Q,MATCH(C22,Jonava!E:E,0),0),"")} -> 718 | J22: {=IFERROR(INDEX(Panevezys2!R:R,MATCH(C22,Panevezys2!E:E,0),0),"")} | K22: =IFERROR(INDEX(Skaudvile!Q:Q,MATCH(C22,Skaudvile!E:E,0),0),"") | L22: =IFERROR(INDEX(Moletai!Q:Q,MATCH(C22,Moletai!E:E,0),0),"") -> 724 | N22: =COUNTIF(D22:M22,">0") -> 3 | O22: =SUM(D22:M22) -> 2097 | P22: =O22/N22 -> 699 | Q22: {=IFERROR(SUMPRODUCT(LARGE(D22:M22,{1;2;3})),"0")} -> 2097 | R22: =IFERROR(INDEX('Bendra įskaita (2025)'!A:A,MATCH(C22,'Bendra įskaita (2025)'!B:B,0),0),"") | S22: =IFERROR(INDEX('Bendra įskaita (2025)'!K:K,MATCH(C22,'Bendra įskaita (2025)'!B:B,0),0),"") | T22: =IFERROR(INDEX('Bendra įskaita (2024)'!A:A,MATCH(C22,'Bendra įskaita (2024)'!B:B,0),0),"") | U22: =IFERROR(INDEX('Bendra įskaita (2024)'!L:L,MATCH(C22,'Bendra įskaita (2024)'!B:B,0),0),"")
A23: 20 | B23: =Table_1[[#This Row],[2025 Vieta]]-A23 -> 25 | C23: Rytis Vasiliauskas | D23: {=IFERROR(INDEX(Panevezys!P:P,MATCH(C23,Panevezys!E:E,0),0),"")} -> 653 | E23: {=IFERROR(INDEX(Kaisiadorys!Q:Q,MATCH(C23,Kaisiadorys!E:E,0),0),"")} | F23: {=IFERROR(INDEX(Veisiejai!Q:Q,MATCH(C23,Veisiejai!E:E,0),0),"")} -> 687 | G23: {=IFERROR(INDEX(Gdanskas!P:P,MATCH(C23,Gdanskas!C:C,0),0),"")} | H23: {=IFERROR(INDEX(Trakai!R:R,MATCH(C23,Trakai!E:E,0),0),"")} | I23: {=IFERROR(INDEX(Jonava!Q:Q,MATCH(C23,Jonava!E:E,0),0),"")} | J23: {=IFERROR(INDEX(Panevezys2!R:R,MATCH(C23,Panevezys2!E:E,0),0),"")} | K23: =IFERROR(INDEX(Skaudvile!Q:Q,MATCH(C23,Skaudvile!E:E,0),0),"") -> 677 | L23: =IFERROR(INDEX(Moletai!Q:Q,MATCH(C23,Moletai!E:E,0),0),"") -> 713 | N23: =COUNTIF(D23:M23,">0") -> 4 | O23: =SUM(D23:M23) -> 2730 | P23: =O23/N23 -> 682.5 | Q23: {=IFERROR(SUMPRODUCT(LARGE(D23:M23,{1;2;3})),"0")} -> 2077 | R23: =IFERROR(INDEX('Bendra įskaita (2025)'!A:A,MATCH(C23,'Bendra įskaita (2025)'!B:B,0),0),"") -> 45 | S23: =IFERROR(INDEX('Bendra įskaita (2025)'!K:K,MATCH(C23,'Bendra įskaita (2025)'!B:B,0),0),"") -> 1 | T23: =IFERROR(INDEX('Bendra įskaita (2024)'!A:A,MATCH(C23,'Bendra įskaita (2024)'!B:B,0),0),"") -> 19 | U23: =IFERROR(INDEX('Bendra įskaita (2024)'!L:L,MATCH(C23,'Bendra įskaita (2024)'!B:B,0),0),"") -> 3
A24: 21 | B24: =Table_1[[#This Row],[2025 Vieta]]-A24 -> 25 | C24: Eglė Čiužaitė | D24: {=IFERROR(INDEX(Panevezys!P:P,MATCH(C24,Panevezys!E:E,0),0),"")} | E24: {=IFERROR(INDEX(Kaisiadorys!Q:Q,MATCH(C24,Kaisiadorys!E:E,0),0),"")} | F24: {=IFERROR(INDEX(Veisiejai!Q:Q,MATCH(C24,Veisiejai!E:E,0),0),"")} -> 643 | G24: {=IFERROR(INDEX(Gdanskas!P:P,MATCH(C24,Gdanskas!C:C,0),0),"")} | H24: {=IFERROR(INDEX(Trakai!R:R,MATCH(C24,Trakai!E:E,0),0),"")} | I24: {=IFERROR(INDEX(Jonava!Q:Q,MATCH(C24,Jonava!E:E,0),0),"")} -> 654 | J24: {=IFERROR(INDEX(Panevezys2!R:R,MATCH(C24,Panevezys2!E:E,0),0),"")} -> 755 | K24: =IFERROR(INDEX(Skaudvile!Q:Q,MATCH(C24,Skaudvile!E:E,0),0),"") | L24: =IFERROR(INDEX(Moletai!Q:Q,MATCH(C24,Moletai!E:E,0),0),"") | N24: =COUNTIF(D24:M24,">0") -> 3 | O24: =SUM(D24:M24) -> 2052 | P24: =O24/N24 -> 684 | Q24: {=IFERROR(SUMPRODUCT(LARGE(D24:M24,{1;2;3})),"0")} -> 2052 | R24: =IFERROR(INDEX('Bendra įskaita (2025)'!A:A,MATCH(C24,'Bendra įskaita (2025)'!B:B,0),0),"") -> 46 | S24: =IFERROR(INDEX('Bendra įskaita (2025)'!K:K,MATCH(C24,'Bendra įskaita (2025)'!B:B,0),0),"") -> 1 | T24: =IFERROR(INDEX('Bendra įskaita (2024)'!A:A,MATCH(C24,'Bendra įskaita (2024)'!B:B,0),0),"") -> 20 | U24: =IFERROR(INDEX('Bendra įskaita (2024)'!L:L,MATCH(C24,'Bendra įskaita (2024)'!B:B,0),0),"") -> 3
A25: 22 | B25: =Table_1[[#This Row],[2025 Vieta]]-A25 -> -4 | C25: Dainius Lučkauskas | D25: {=IFERROR(INDEX(Panevezys!P:P,MATCH(C25,Panevezys!E:E,0),0),"")} -> 645 | E25: {=IFERROR(INDEX(Kaisiadorys!Q:Q,MATCH(C25,Kaisiadorys!E:E,0),0),"")} -> 651 | F25: {=IFERROR(INDEX(Veisiejai!Q:Q,MATCH(C25,Veisiejai!E:E,0),0),"")} | G25: {=IFERROR(INDEX(Gdanskas!P:P,MATCH(C25,Gdanskas!C:C,0),0),"")} | H25: {=IFERROR(INDEX(Trakai!R:R,MATCH(C25,Trakai!E:E,0),0),"")} -> 680 | I25: {=IFERROR(INDEX(Jonava!Q:Q,MATCH(C25,Jonava!E:E,0),0),"")} -> 702 | J25: {=IFERROR(INDEX(Panevezys2!R:R,MATCH(C25,Panevezys2!E:E,0),0),"")} | K25: =IFERROR(INDEX(Skaudvile!Q:Q,MATCH(C25,Skaudvile!E:E,0),0),"") | L25: =IFERROR(INDEX(Moletai!Q:Q,MATCH(C25,Moletai!E:E,0),0),"") | N25: =COUNTIF(D25:M25,">0") -> 4 | O25: =SUM(D25:M25) -> 2678 | P25: =O25/N25 -> 669.5 | Q25: {=IFERROR(SUMPRODUCT(LARGE(D25:M25,{1;2;3})),"0")} -> 2033 | R25: =IFERROR(INDEX('Bendra įskaita (2025)'!A:A,MATCH(C25,'Bendra įskaita (2025)'!B:B,0),0),"") -> 18 | S25: =IFERROR(INDEX('Bendra įskaita (2025)'!K:K,MATCH(C25,'Bendra įskaita (2025)'!B:B,0),0),"") -> 3 | T25: =IFERROR(INDEX('Bendra įskaita (2024)'!A:A,MATCH(C25,'Bendra įskaita (2024)'!B:B,0),0),"") -> 22 | U25: =IFERROR(INDEX('Bendra įskaita (2024)'!L:L,MATCH(C25,'Bendra įskaita (2024)'!B:B,0),0),"") -> 2
A26: 23 | B26: =Table_1[[#This Row],[2025 Vieta]]-A26 -> 24 | C26: Giedrius Danėlius | D26: {=IFERROR(INDEX(Panevezys!P:P,MATCH(C26,Panevezys!E:E,0),0),"")} -> 659 | E26: {=IFERROR(INDEX(Kaisiadorys!Q:Q,MATCH(C26,Kaisiadorys!E:E,0),0),"")} | F26: {=IFERROR(INDEX(Veisiejai!Q:Q,MATCH(C26,Veisiejai!E:E,0),0),"")} -> 645 | G26: {=IFERROR(INDEX(Gdanskas!P:P,MATCH(C26,Gdanskas!C:C,0),0),"")} | H26: {=IFERROR(INDEX(Trakai!R:R,MATCH(C26,Trakai!E:E,0),0),"")} | I26: {=IFERROR(INDEX(Jonava!Q:Q,MATCH(C26,Jonava!E:E,0),0),"")} -> 695 | J26: {=IFERROR(INDEX(Panevezys2!R:R,MATCH(C26,Panevezys2!E:E,0),0),"")} | K26: =IFERROR(INDEX(Skaudvile!Q:Q,MATCH(C26,Skaudvile!E:E,0),0),"") | L26: =IFERROR(INDEX(Moletai!Q:Q,MATCH(C26,Moletai!E:E,0),0),"") -> 0 | N26: =COUNTIF(D26:M26,">0") -> 3 | O26: =SUM(D26:M26) -> 1999 | P26: =O26/N26 -> 666.33333 | Q26: {=IFERROR(SUMPRODUCT(LARGE(D26:M26,{1;2;3})),"0")} -> 1999 | R26: =IFERROR(INDEX('Bendra įskaita (2025)'!A:A,MATCH(C26,'Bendra įskaita (2025)'!B:B,0),0),"") -> 47 | S26: =IFERROR(INDEX('Bendra įskaita (2025)'!K:K,MATCH(C26,'Bendra įskaita (2025)'!B:B,0),0),"") -> 1 | T26: =IFERROR(INDEX('Bendra įskaita (2024)'!A:A,MATCH(C26,'Bendra įskaita (2024)'!B:B,0),0),"") -> 64 | U26: =IFERROR(INDEX('Bendra įskaita (2024)'!L:L,MATCH(C26,'Bendra įskaita (2024)'!B:B,0),0),"") -> 0
A27: 24 | B27: =Table_1[[#This Row],[2025 Vieta]]-A27 -> 27 | C27: Liudmila Volbikienė | D27: {=IFERROR(INDEX(Panevezys!P:P,MATCH(C27,Panevezys!E:E,0),0),"")} -> 630 | E27: {=IFERROR(INDEX(Kaisiadorys!Q:Q,MATCH(C27,Kaisiadorys!E:E,0),0),"")} | F27: {=IFERROR(INDEX(Veisiejai!Q:Q,MATCH(C27,Veisiejai!E:E,0),0),"")} | G27: {=IFERROR(INDEX(Gdanskas!P:P,MATCH(C27,Gdanskas!C:C,0),0),"")} -> 683 | H27: {=IFERROR(INDEX(Trakai!R:R,MATCH(C27,Trakai!E:E,0),0),"")} | I27: {=IFERROR(INDEX(Jonava!Q:Q,MATCH(C27,Jonava!E:E,0),0),"")} | J27: {=IFERROR(INDEX(Panevezys2!R:R,MATCH(C27,Panevezys2!E:E,0),0),"")} | K27: =IFERROR(INDEX(Skaudvile!Q:Q,MATCH(C27,Skaudvile!E:E,0),0),"") | L27: =IFERROR(INDEX(Moletai!Q:Q,MATCH(C27,Moletai!E:E,0),0),"") -> 665 | N27: =COUNTIF(D27:M27,">0") -> 3 | O27: =SUM(D27:M27) -> 1978 | P27: =O27/N27 -> 659.33333 | Q27: {=IFERROR(SUMPRODUCT(LARGE(D27:M27,{1;2;3})),"0")} -> 1978 | R27: =IFERROR(INDEX('Bendra įskaita (2025)'!A:A,MATCH(C27,'Bendra įskaita (2025)'!B:B,0),0),"") -> 51 | S27: =IFERROR(INDEX('Bendra įskaita (2025)'!K:K,MATCH(C27,'Bendra įskaita (2025)'!B:B,0),0),"") -> 0 | T27: 78 | U27: 0
A28: 25 | B28: =Table_1[[#This Row],[2025 Vieta]]-A27 -> -7 | C28: Austėja Letukienė | D28: {=IFERROR(INDEX(Panevezys!P:P,MATCH(C28,Panevezys!E:E,0),0),"")} | E28: {=IFERROR(INDEX(Kaisiadorys!Q:Q,MATCH(C28,Kaisiadorys!E:E,0),0),"")} | F28: {=IFERROR(INDEX(Veisiejai!Q:Q,MATCH(C28,Veisiejai!E:E,0),0),"")} | G28: {=IFERROR(INDEX(Gdanskas!P:P,MATCH(C28,Gdanskas!C:C,0),0),"")} | H28: {=IFERROR(INDEX(Trakai!R:R,MATCH(C28,Trakai!E:E,0),0),"")} -> 619 | I28: {=IFERROR(INDEX(Jonava!Q:Q,MATCH(C28,Jonava!E:E,0),0),"")} -> 695 | J28: {=IFERROR(INDEX(Panevezys2!R:R,MATCH(C28,Panevezys2!E:E,0),0),"")} | K28: =IFERROR(INDEX(Skaudvile!Q:Q,MATCH(C28,Skaudvile!E:E,0),0),"") -> 652 | L28: =IFERROR(INDEX(Moletai!Q:Q,MATCH(C28,Moletai!E:E,0),0),"") | N28: =COUNTIF(D28:M28,">0") -> 3 | O28: =SUM(D28:M28) -> 1966 | P28: =O28/N28 -> 655.33333 | Q28: {=IFERROR(SUMPRODUCT(LARGE(D28:M28,{1;2;3})),"0")} -> 1966 | R28: =IFERROR(INDEX('Bendra įskaita (2025)'!A:A,MATCH(C28,'Bendra įskaita (2025)'!B:B,0),0),"") -> 17 | S28: =IFERROR(INDEX('Bendra įskaita (2025)'!K:K,MATCH(C28,'Bendra įskaita (2025)'!B:B,0),0),"") -> 5 | T28: =IFERROR(INDEX('Bendra įskaita (2024)'!A:A,MATCH(C28,'Bendra įskaita (2024)'!B:B,0),0),"") | U28: =IFERROR(INDEX('Bendra įskaita (2024)'!L:L,MATCH(C28,'Bendra įskaita (2024)'!B:B,0),0),"")
A29: 26 | B29: =Table_1[[#This Row],[2025 Vieta]]-A28 -> 26 | C29: Gabrielė Gruslienė | D29: {=IFERROR(INDEX(Panevezys!P:P,MATCH(C29,Panevezys!E:E,0),0),"")} | E29: {=IFERROR(INDEX(Kaisiadorys!Q:Q,MATCH(C29,Kaisiadorys!E:E,0),0),"")} | F29: {=IFERROR(INDEX(Veisiejai!Q:Q,MATCH(C29,Veisiejai!E:E,0),0),"")} -> 627 | G29: {=IFERROR(INDEX(Gdanskas!P:P,MATCH(C29,Gdanskas!C:C,0),0),"")} -> 604 | H29: {=IFERROR(INDEX(Trakai!R:R,MATCH(C29,Trakai!E:E,0),0),"")} -> 568 | I29: {=IFERROR(INDEX(Jonava!Q:Q,MATCH(C29,Jonava!E:E,0),0),"")} | J29: {=IFERROR(INDEX(Panevezys2!R:R,MATCH(C29,Panevezys2!E:E,0),0),"")} | K29: =IFERROR(INDEX(Skaudvile!Q:Q,MATCH(C29,Skaudvile!E:E,0),0),"") | L29: =IFERROR(INDEX(Moletai!Q:Q,MATCH(C29,Moletai!E:E,0),0),"") | N29: =COUNTIF(D29:M29,">0") -> 3 | O29: =SUM(D29:M29) -> 1799 | P29: =O29/N29 -> 599.66667 | Q29: {=IFERROR(SUMPRODUCT(LARGE(D29:M29,{1;2;3})),"0")} -> 1799 | R29: =IFERROR(INDEX('Bendra įskaita (2025)'!A:A,MATCH(C29,'Bendra įskaita (2025)'!B:B,0),0),"") -> 51 | S29: =IFERROR(INDEX('Bendra įskaita (2025)'!K:K,MATCH(C29,'Bendra įskaita (2025)'!B:B,0),0),"") -> 0 | T29: =IFERROR(INDEX('Bendra įskaita (2024)'!A:A,MATCH(C29,'Bendra įskaita (2024)'!B:B,0),0),"") -> 48 | U29: =IFERROR(INDEX('Bendra įskaita (2024)'!L:L,MATCH(C29,'Bendra įskaita (2024)'!B:B,0),0),"") -> 1
A30: 27 | B30: =Table_1[[#This Row],[2025 Vieta]]-A29 -> 22 | C30: Aurimas Gudaitis | D30: {=IFERROR(INDEX(Panevezys!P:P,MATCH(C30,Panevezys!E:E,0),0),"")} | E30: {=IFERROR(INDEX(Kaisiadorys!Q:Q,MATCH(C30,Kaisiadorys!E:E,0),0),"")} | F30: {=IFERROR(INDEX(Veisiejai!Q:Q,MATCH(C30,Veisiejai!E:E,0),0),"")} | G30: {=IFERROR(INDEX(Gdanskas!P:P,MATCH(C30,Gdanskas!C:C,0),0),"")} | H30: {=IFERROR(INDEX(Trakai!R:R,MATCH(C30,Trakai!E:E,0),0),"")} | I30: {=IFERROR(INDEX(Jonava!Q:Q,MATCH(C30,Jonava!E:E,0),0),"")} | J30: {=IFERROR(INDEX(Panevezys2!R:R,MATCH(C30,Panevezys2!E:E,0),0),"")} | K30: =IFERROR(INDEX(Skaudvile!Q:Q,MATCH(C30,Skaudvile!E:E,0),0),"") -> 788 | L30: =IFERROR(INDEX(Moletai!Q:Q,MATCH(C30,Moletai!E:E,0),0),"") | N30: =COUNTIF(D30:M30,">0") -> 1 | O30: =SUM(D30:M30) -> 788 | P30: =O30/N30 -> 788 | Q30: {=IFERROR(SUMPRODUCT(LARGE(D30:M30,{1;2;3})),"0")} -> 0 | R30: =IFERROR(INDEX('Bendra įskaita (2025)'!A:A,MATCH(C30,'Bendra įskaita (2025)'!B:B,0),0),"") -> 48 | S30: =IFERROR(INDEX('Bendra įskaita (2025)'!K:K,MATCH(C30,'Bendra įskaita (2025)'!B:B,0),0),"") -> 1 | T30: =IFERROR(INDEX('Bendra įskaita (2024)'!A:A,MATCH(C30,'Bendra įskaita (2024)'!B:B,0),0),"") -> 58 | U30: =IFERROR(INDEX('Bendra įskaita (2024)'!L:L,MATCH(C30,'Bendra įskaita (2024)'!B:B,0),0),"") -> 0
A31: 28 | B31: =Table_1[[#This Row],[2025 Vieta]]-A30 -> 22 | C31: Emilis Urbanavičius | D31: {=IFERROR(INDEX(Panevezys!P:P,MATCH(C31,Panevezys!E:E,0),0),"")} | E31: {=IFERROR(INDEX(Kaisiadorys!Q:Q,MATCH(C31,Kaisiadorys!E:E,0),0),"")} | F31: {=IFERROR(INDEX(Veisiejai!Q:Q,MATCH(C31,Veisiejai!E:E,0),0),"")} | G31: {=IFERROR(INDEX(Gdanskas!P:P,MATCH(C31,Gdanskas!C:C,0),0),"")} | H31: {=IFERROR(INDEX(Trakai!R:R,MATCH(C31,Trakai!E:E,0),0),"")} | I31: {=IFERROR(INDEX(Jonava!Q:Q,MATCH(C31,Jonava!E:E,0),0),"")} | J31: {=IFERROR(INDEX(Panevezys2!R:R,MATCH(C31,Panevezys2!E:E,0),0),"")} | K31: =IFERROR(INDEX(Skaudvile!Q:Q,MATCH(C31,Skaudvile!E:E,0),0),"") | L31: =IFERROR(INDEX(Moletai!Q:Q,MATCH(C31,Moletai!E:E,0),0),"") | N31: 5 | O31: =SUM(D31:M31) -> 0 | P31: 0 | Q31: {=IFERROR(SUMPRODUCT(LARGE(D31:M31,{1;2;3})),"0")} -> 0 | R31: =IFERROR(INDEX('Bendra įskaita (2025)'!A:A,MATCH(C31,'Bendra įskaita (2025)'!B:B,0),0),"") -> 49 | S31: =IFERROR(INDEX('Bendra įskaita (2025)'!K:K,MATCH(C31,'Bendra įskaita (2025)'!B:B,0),0),"") -> 2 | T31: =IFERROR(INDEX('Bendra įskaita (2024)'!A:A,MATCH(C31,'Bendra įskaita (2024)'!B:B,0),0),"") -> 62 | U31: =IFERROR(INDEX('Bendra įskaita (2024)'!L:L,MATCH(C31,'Bendra įskaita (2024)'!B:B,0),0),"") -> 0
A32: 29 | B32: =Table_1[[#This Row],[2025 Vieta]]-A31 -> 0 | C32: Rūta Juškevičiūtė | D32: {=IFERROR(INDEX(Panevezys!P:P,MATCH(C32,Panevezys!E:E,0),0),"")} | E32: {=IFERROR(INDEX(Kaisiadorys!Q:Q,MATCH(C32,Kaisiadorys!E:E,0),0),"")} | F32: {=IFERROR(INDEX(Veisiejai!Q:Q,MATCH(C32,Veisiejai!E:E,0),0),"")} | G32: {=IFERROR(INDEX(Gdanskas!P:P,MATCH(C32,Gdanskas!C:C,0),0),"")} -> 905 | H32: {=IFERROR(INDEX(Trakai!R:R,MATCH(C32,Trakai!E:E,0),0),"")} | I32: {=IFERROR(INDEX(Jonava!Q:Q,MATCH(C32,Jonava!E:E,0),0),"")} | J32: {=IFERROR(INDEX(Panevezys2!R:R,MATCH(C32,Panevezys2!E:E,0),0),"")} | K32: =IFERROR(INDEX(Skaudvile!Q:Q,MATCH(C32,Skaudvile!E:E,0),0),"") | L32: =IFERROR(INDEX(Moletai!Q:Q,MATCH(C32,Moletai!E:E,0),0),"") | N32: =COUNTIF(D32:M32,">0") -> 1 | O32: =SUM(D32:M32) -> 905 | P32: =O32/N32 -> 905 | Q32: {=IFERROR(SUMPRODUCT(LARGE(D32:M32,{1;2;3})),"0")} -> 0 | R32: =IFERROR(INDEX('Bendra įskaita (2025)'!A:A,MATCH(C32,'Bendra įskaita (2025)'!B:B,0),0),"") -> 28 | S32: =IFERROR(INDEX('Bendra įskaita (2025)'!K:K,MATCH(C32,'Bendra įskaita (2025)'!B:B,0),0),"") -> 1 | T32: =IFERROR(INDEX('Bendra įskaita (2024)'!A:A,MATCH(C32,'Bendra įskaita (2024)'!B:B,0),0),"") -> 6 | U32: =IFERROR(INDEX('Bendra įskaita (2024)'!L:L,MATCH(C32,'Bendra įskaita (2024)'!B:B,0),0),"") -> 3
A33: 30 | B33: =Table_1[[#This Row],[2025 Vieta]]-A32 -> 22 | C33: Ernestas Česonis | D33: {=IFERROR(INDEX(Panevezys!P:P,MATCH(C33,Panevezys!E:E,0),0),"")} | E33: {=IFERROR(INDEX(Kaisiadorys!Q:Q,MATCH(C33,Kaisiadorys!E:E,0),0),"")} -> 886 | F33: {=IFERROR(INDEX(Veisiejai!Q:Q,MATCH(C33,Veisiejai!E:E,0),0),"")} | G33: {=IFERROR(INDEX(Gdanskas!P:P,MATCH(C33,Gdanskas!C:C,0),0),"")} | H33: {=IFERROR(INDEX(Trakai!R:R,MATCH(C33,Trakai!E:E,0),0),"")} | I33: {=IFERROR(INDEX(Jonava!Q:Q,MATCH(C33,Jonava!E:E,0),0),"")} | J33: {=IFERROR(INDEX(Panevezys2!R:R,MATCH(C33,Panevezys2!E:E,0),0),"")} | K33: =IFERROR(INDEX(Skaudvile!Q:Q,MATCH(C33,Skaudvile!E:E,0),0),"") | L33: =IFERROR(INDEX(Moletai!Q:Q,MATCH(C33,Moletai!E:E,0),0),"") | N33: =COUNTIF(D33:M33,">0") -> 1 | O33: =SUM(D33:M33) -> 886 | P33: =O33/N33 -> 886 | Q33: {=IFERROR(SUMPRODUCT(LARGE(D33:M33,{1;2;3})),"0")} -> 0 | R33: =IFERROR(INDEX('Bendra įskaita (2025)'!A:A,MATCH(C33,'Bendra įskaita (2025)'!B:B,0),0),"") -> 51 | S33: =IFERROR(INDEX('Bendra įskaita (2025)'!K:K,MATCH(C33,'Bendra įskaita (2025)'!B:B,0),0),"") -> 0 | T33: =IFERROR(INDEX('Bendra įskaita (2024)'!A:A,MATCH(C33,'Bendra įskaita (2024)'!B:B,0),0),"") -> 30 | U33: =IFERROR(INDEX('Bendra įskaita (2024)'!L:L,MATCH(C33,'Bendra įskaita (2024)'!B:B,0),0),"") -> 1
A34: 31 | B34: =Table_1[[#This Row],[2025 Vieta]]-A33 -> -23 | C34: Aleksej Kaminskij | D34: {=IFERROR(INDEX(Panevezys!P:P,MATCH(C34,Panevezys!E:E,0),0),"")} -> 818 | E34: {=IFERROR(INDEX(Kaisiadorys!Q:Q,MATCH(C34,Kaisiadorys!E:E,0),0),"")} | F34: {=IFERROR(INDEX(Veisiejai!Q:Q,MATCH(C34,Veisiejai!E:E,0),0),"")} | G34: {=IFERROR(INDEX(Gdanskas!P:P,MATCH(C34,Gdanskas!C:C,0),0),"")} -> 952 | H34: {=IFERROR(INDEX(Trakai!R:R,MATCH(C34,Trakai!E:E,0),0),"")} | I34: {=IFERROR(INDEX(Jonava!Q:Q,MATCH(C34,Jonava!E:E,0),0),"")} | J34: {=IFERROR(INDEX(Panevezys2!R:R,MATCH(C34,Panevezys2!E:E,0),0),"")} | K34: =IFERROR(INDEX(Skaudvile!Q:Q,MATCH(C34,Skaudvile!E:E,0),0),"") | L34: =IFERROR(INDEX(Moletai!Q:Q,MATCH(C34,Moletai!E:E,0),0),"") | N34: =COUNTIF(D34:M34,">0") -> 2 | O34: =SUM(D34:M34) -> 1770 | P34: =O34/N34 -> 885 | Q34: {=IFERROR(SUMPRODUCT(LARGE(D34:M34,{1;2;3})),"0")} -> 0 | R34: =IFERROR(INDEX('Bendra įskaita (2025)'!A:A,MATCH(C34,'Bendra įskaita (2025)'!B:B,0),0),"") -> 7 | S34: =IFERROR(INDEX('Bendra įskaita (2025)'!K:K,MATCH(C34,'Bendra įskaita (2025)'!B:B,0),0),"") -> 3 | T34: =IFERROR(INDEX('Bendra įskaita (2024)'!A:A,MATCH(C34,'Bendra įskaita (2024)'!B:B,0),0),"") -> 11 | U34: =IFERROR(INDEX('Bendra įskaita (2024)'!L:L,MATCH(C34,'Bendra įskaita (2024)'!B:B,0),0),"") -> 3
A35: 32 | B35: =Table_1[[#This Row],[2025 Vieta]]-A34 -> -6 | C35: Vytas Vasilevičius | D35: {=IFERROR(INDEX(Panevezys!P:P,MATCH(C35,Panevezys!E:E,0),0),"")} | E35: {=IFERROR(INDEX(Kaisiadorys!Q:Q,MATCH(C35,Kaisiadorys!E:E,0),0),"")} | F35: {=IFERROR(INDEX(Veisiejai!Q:Q,MATCH(C35,Veisiejai!E:E,0),0),"")} | G35: {=IFERROR(INDEX(Gdanskas!P:P,MATCH(C35,Gdanskas!C:C,0),0),"")} | H35: {=IFERROR(INDEX(Trakai!R:R,MATCH(C35,Trakai!E:E,0),0),"")} | I35: {=IFERROR(INDEX(Jonava!Q:Q,MATCH(C35,Jonava!E:E,0),0),"")} | J35: {=IFERROR(INDEX(Panevezys2!R:R,MATCH(C35,Panevezys2!E:E,0),0),"")} | K35: =IFERROR(INDEX(Skaudvile!Q:Q,MATCH(C35,Skaudvile!E:E,0),0),"") | L35: =IFERROR(INDEX(Moletai!Q:Q,MATCH(C35,Moletai!E:E,0),0),"") -> 863 | N35: =COUNTIF(D35:M35,">0") -> 1 | O35: =SUM(D35:M35) -> 863 | P35: =O35/N35 -> 863 | Q35: {=IFERROR(SUMPRODUCT(LARGE(D35:M35,{1;2;3})),"0")} -> 0 | R35: =IFERROR(INDEX('Bendra įskaita (2025)'!A:A,MATCH(C35,'Bendra įskaita (2025)'!B:B,0),0),"") -> 25 | S35: =IFERROR(INDEX('Bendra įskaita (2025)'!K:K,MATCH(C35,'Bendra įskaita (2025)'!B:B,0),0),"") -> 1 | T35: =IFERROR(INDEX('Bendra įskaita (2024)'!A:A,MATCH(C35,'Bendra įskaita (2024)'!B:B,0),0),"") -> 3 | U35: =IFERROR(INDEX('Bendra įskaita (2024)'!L:L,MATCH(C35,'Bendra įskaita (2024)'!B:B,0),0),"") -> 3
A36: 33 | B36: =Table_1[[#This Row],[2025 Vieta]]-A35 -> -26 | C36: Vytautas Vaičiulis | D36: {=IFERROR(INDEX(Panevezys!P:P,MATCH(C36,Panevezys!E:E,0),0),"")} | E36: {=IFERROR(INDEX(Kaisiadorys!Q:Q,MATCH(C36,Kaisiadorys!E:E,0),0),"")} -> 808 | F36: {=IFERROR(INDEX(Veisiejai!Q:Q,MATCH(C36,Veisiejai!E:E,0),0),"")} | G36: {=IFERROR(INDEX(Gdanskas!P:P,MATCH(C36,Gdanskas!C:C,0),0),"")} | H36: {=IFERROR(INDEX(Trakai!R:R,MATCH(C36,Trakai!E:E,0),0),"")} -> 879 | I36: {=IFERROR(INDEX(Jonava!Q:Q,MATCH(C36,Jonava!E:E,0),0),"")} | J36: {=IFERROR(INDEX(Panevezys2!R:R,MATCH(C36,Panevezys2!E:E,0),0),"")} | K36: =IFERROR(INDEX(Skaudvile!Q:Q,MATCH(C36,Skaudvile!E:E,0),0),"") | L36: =IFERROR(INDEX(Moletai!Q:Q,MATCH(C36,Moletai!E:E,0),0),"") | N36: =COUNTIF(D36:M36,">0") -> 2 | O36: =SUM(D36:M36) -> 1687 | P36: =O36/N36 -> 843.5 | Q36: {=IFERROR(SUMPRODUCT(LARGE(D36:M36,{1;2;3})),"0")} -> 0 | R36: =IFERROR(INDEX('Bendra įskaita (2025)'!A:A,MATCH(C36,'Bendra įskaita (2025)'!B:B,0),0),"") -> 6 | S36: =IFERROR(INDEX('Bendra įskaita (2025)'!K:K,MATCH(C36,'Bendra įskaita (2025)'!B:B,0),0),"") -> 3 | T36: =IFERROR(INDEX('Bendra įskaita (2024)'!A:A,MATCH(C36,'Bendra įskaita (2024)'!B:B,0),0),"") -> 9 | U36: =IFERROR(INDEX('Bendra įskaita (2024)'!L:L,MATCH(C36,'Bendra įskaita (2024)'!B:B,0),0),"") -> 5
A37: 34 | B37: =Table_1[[#This Row],[2025 Vieta]]-A36 -> 18 | C37: Irmantas Budrys | D37: {=IFERROR(INDEX(Panevezys!P:P,MATCH(C37,Panevezys!E:E,0),0),"")} | E37: {=IFERROR(INDEX(Kaisiadorys!Q:Q,MATCH(C37,Kaisiadorys!E:E,0),0),"")} | F37: {=IFERROR(INDEX(Veisiejai!Q:Q,MATCH(C37,Veisiejai!E:E,0),0),"")} | G37: {=IFERROR(INDEX(Gdanskas!P:P,MATCH(C37,Gdanskas!C:C,0),0),"")} -> 790 | H37: {=IFERROR(INDEX(Trakai!R:R,MATCH(C37,Trakai!E:E,0),0),"")} | I37: {=IFERROR(INDEX(Jonava!Q:Q,MATCH(C37,Jonava!E:E,0),0),"")} | J37: {=IFERROR(INDEX(Panevezys2!R:R,MATCH(C37,Panevezys2!E:E,0),0),"")} | K37: =IFERROR(INDEX(Skaudvile!Q:Q,MATCH(C37,Skaudvile!E:E,0),0),"") | L37: =IFERROR(INDEX(Moletai!Q:Q,MATCH(C37,Moletai!E:E,0),0),"") | N37: =COUNTIF(D37:M37,">0") -> 1 | O37: =SUM(D37:M37) -> 790 | P37: =O37/N37 -> 790 | Q37: {=IFERROR(SUMPRODUCT(LARGE(D37:M37,{1;2;3})),"0")} -> 0 | R37: =IFERROR(INDEX('Bendra įskaita (2025)'!A:A,MATCH(C37,'Bendra įskaita (2025)'!B:B,0),0),"") -> 51 | S37: =IFERROR(INDEX('Bendra įskaita (2025)'!K:K,MATCH(C37,'Bendra įskaita (2025)'!B:B,0),0),"") -> 0 | T37: =IFERROR(INDEX('Bendra įskaita (2024)'!A:A,MATCH(C37,'Bendra įskaita (2024)'!B:B,0),0),"") -> 38 | U37: =IFERROR(INDEX('Bendra įskaita (2024)'!L:L,MATCH(C37,'Bendra įskaita (2024)'!B:B,0),0),"") -> 1
A38: 35 | B38: =Table_1[[#This Row],[2025 Vieta]]-A37 -> -3 | C38: Nerijus Beniušis | D38: {=IFERROR(INDEX(Panevezys!P:P,MATCH(C38,Panevezys!E:E,0),0),"")} | E38: {=IFERROR(INDEX(Kaisiadorys!Q:Q,MATCH(C38,Kaisiadorys!E:E,0),0),"")} | F38: {=IFERROR(INDEX(Veisiejai!Q:Q,MATCH(C38,Veisiejai!E:E,0),0),"")} | G38: {=IFERROR(INDEX(Gdanskas!P:P,MATCH(C38,Gdanskas!C:C,0),0),"")} | H38: {=IFERROR(INDEX(Trakai!R:R,MATCH(C38,Trakai!E:E,0),0),"")} -> 789 | I38: {=IFERROR(INDEX(Jonava!Q:Q,MATCH(C38,Jonava!E:E,0),0),"")} | J38: {=IFERROR(INDEX(Panevezys2!R:R,MATCH(C38,Panevezys2!E:E,0),0),"")} | K38: =IFERROR(INDEX(Skaudvile!Q:Q,MATCH(C38,Skaudvile!E:E,0),0),"") | L38: =IFERROR(INDEX(Moletai!Q:Q,MATCH(C38,Moletai!E:E,0),0),"") | N38: =COUNTIF(D38:M38,">0") -> 1 | O38: =SUM(D38:M38) -> 789 | P38: =O38/N38 -> 789 | Q38: {=IFERROR(SUMPRODUCT(LARGE(D38:M38,{1;2;3})),"0")} -> 0 | R38: =IFERROR(INDEX('Bendra įskaita (2025)'!A:A,MATCH(C38,'Bendra įskaita (2025)'!B:B,0),0),"") -> 31 | S38: =IFERROR(INDEX('Bendra įskaita (2025)'!K:K,MATCH(C38,'Bendra įskaita (2025)'!B:B,0),0),"") -> 2 | T38: =IFERROR(INDEX('Bendra įskaita (2024)'!A:A,MATCH(C38,'Bendra įskaita (2024)'!B:B,0),0),"") -> 4 | U38: =IFERROR(INDEX('Bendra įskaita (2024)'!L:L,MATCH(C38,'Bendra įskaita (2024)'!B:B,0),0),"") -> 4
A39: 36 | B39: =Table_1[[#This Row],[2025 Vieta]]-A38 -> 1 | C39: Arvydas Čiužas | D39: {=IFERROR(INDEX(Panevezys!P:P,MATCH(C39,Panevezys!E:E,0),0),"")} | E39: {=IFERROR(INDEX(Kaisiadorys!Q:Q,MATCH(C39,Kaisiadorys!E:E,0),0),"")} | F39: {=IFERROR(INDEX(Veisiejai!Q:Q,MATCH(C39,Veisiejai!E:E,0),0),"")} | G39: {=IFERROR(INDEX(Gdanskas!P:P,MATCH(C39,Gdanskas!C:C,0),0),"")} | H39: {=IFERROR(INDEX(Trakai!R:R,MATCH(C39,Trakai!E:E,0),0),"")} -> 781 | I39: {=IFERROR(INDEX(Jonava!Q:Q,MATCH(C39,Jonava!E:E,0),0),"")} | J39: {=IFERROR(INDEX(Panevezys2!R:R,MATCH(C39,Panevezys2!E:E,0),0),"")} | K39: =IFERROR(INDEX(Skaudvile!Q:Q,MATCH(C39,Skaudvile!E:E,0),0),"") | L39: =IFERROR(INDEX(Moletai!Q:Q,MATCH(C39,Moletai!E:E,0),0),"") | N39: =COUNTIF(D39:M39,">0") -> 1 | O39: =SUM(D39:M39) -> 781 | P39: =O39/N39 -> 781 | Q39: {=IFERROR(SUMPRODUCT(LARGE(D39:M39,{1;2;3})),"0")} -> 0 | R39: =IFERROR(INDEX('Bendra įskaita (2025)'!A:A,MATCH(C39,'Bendra įskaita (2025)'!B:B,0),0),"") -> 36 | S39: =IFERROR(INDEX('Bendra įskaita (2025)'!K:K,MATCH(C39,'Bendra įskaita (2025)'!B:B,0),0),"") -> 1 | T39: =IFERROR(INDEX('Bendra įskaita (2024)'!A:A,MATCH(C39,'Bendra įskaita (2024)'!B:B,0),0),"") -> 56 | U39: =IFERROR(INDEX('Bendra įskaita (2024)'!L:L,MATCH(C39,'Bendra įskaita (2024)'!B:B,0),0),"") -> 0
A40: 37 | B40: NEW | C40: Valdemaras Sivickij | D40: {=IFERROR(INDEX(Panevezys!P:P,MATCH(C40,Panevezys!E:E,0),0),"")} | E40: {=IFERROR(INDEX(Kaisiadorys!Q:Q,MATCH(C40,Kaisiadorys!E:E,0),0),"")} | F40: {=IFERROR(INDEX(Veisiejai!Q:Q,MATCH(C40,Veisiejai!E:E,0),0),"")} | G40: {=IFERROR(INDEX(Gdanskas!P:P,MATCH(C40,Gdanskas!C:C,0),0),"")} | H40: {=IFERROR(INDEX(Trakai!R:R,MATCH(C40,Trakai!E:E,0),0),"")} -> 778 | I40: {=IFERROR(INDEX(Jonava!Q:Q,MATCH(C40,Jonava!E:E,0),0),"")} | J40: {=IFERROR(INDEX(Panevezys2!R:R,MATCH(C40,Panevezys2!E:E,0),0),"")} | K40: =IFERROR(INDEX(Skaudvile!Q:Q,MATCH(C40,Skaudvile!E:E,0),0),"") | L40: =IFERROR(INDEX(Moletai!Q:Q,MATCH(C40,Moletai!E:E,0),0),"") | N40: =COUNTIF(D40:M40,">0") -> 1 | O40: =SUM(D40:M40) -> 778 | P40: =O40/N40 -> 778 | Q40: {=IFERROR(SUMPRODUCT(LARGE(D40:M40,{1;2;3})),"0")} -> 0 | R40: =IFERROR(INDEX('Bendra įskaita (2025)'!A:A,MATCH(C40,'Bendra įskaita (2025)'!B:B,0),0),"") | S40: =IFERROR(INDEX('Bendra įskaita (2025)'!K:K,MATCH(C40,'Bendra įskaita (2025)'!B:B,0),0),"") | T40: =IFERROR(INDEX('Bendra įskaita (2024)'!A:A,MATCH(C40,'Bendra įskaita (2024)'!B:B,0),0),"") | U40: =IFERROR(INDEX('Bendra įskaita (2024)'!L:L,MATCH(C40,'Bendra įskaita (2024)'!B:B,0),0),"")
A41: 38 | B41: =Table_1[[#This Row],[2025 Vieta]]-A40 -> -2 | C41: Rūta Jazepčikienė | D41: {=IFERROR(INDEX(Panevezys!P:P,MATCH(C41,Panevezys!E:E,0),0),"")} | E41: {=IFERROR(INDEX(Kaisiadorys!Q:Q,MATCH(C41,Kaisiadorys!E:E,0),0),"")} -> 760 | F41: {=IFERROR(INDEX(Veisiejai!Q:Q,MATCH(C41,Veisiejai!E:E,0),0),"")} | G41: {=IFERROR(INDEX(Gdanskas!P:P,MATCH(C41,Gdanskas!C:C,0),0),"")} | H41: {=IFERROR(INDEX(Trakai!R:R,MATCH(C41,Trakai!E:E,0),0),"")} | I41: {=IFERROR(INDEX(Jonava!Q:Q,MATCH(C41,Jonava!E:E,0),0),"")} | J41: {=IFERROR(INDEX(Panevezys2!R:R,MATCH(C41,Panevezys2!E:E,0),0),"")} | K41: =IFERROR(INDEX(Skaudvile!Q:Q,MATCH(C41,Skaudvile!E:E,0),0),"") | L41: =IFERROR(INDEX(Moletai!Q:Q,MATCH(C41,Moletai!E:E,0),0),"") -> 765 | N41: =COUNTIF(D41:M41,">0") -> 2 | O41: =SUM(D41:M41) -> 1525 | P41: =O41/N41 -> 762.5 | Q41: {=IFERROR(SUMPRODUCT(LARGE(D41:M41,{1;2;3})),"0")} -> 0 | R41: =IFERROR(INDEX('Bendra įskaita (2025)'!A:A,MATCH(C41,'Bendra įskaita (2025)'!B:B,0),0),"") -> 35 | S41: =IFERROR(INDEX('Bendra įskaita (2025)'!K:K,MATCH(C41,'Bendra įskaita (2025)'!B:B,0),0),"") -> 1 | T41: =IFERROR(INDEX('Bendra įskaita (2024)'!A:A,MATCH(C41,'Bendra įskaita (2024)'!B:B,0),0),"") | U41: =IFERROR(INDEX('Bendra įskaita (2024)'!L:L,MATCH(C41,'Bendra įskaita (2024)'!B:B,0),0),"")
A42: 39 | B42: =Table_1[[#This Row],[2025 Vieta]]-A41 -> -23 | C42: Mark Zaičik | D42: {=IFERROR(INDEX(Panevezys!P:P,MATCH(C42,Panevezys!E:E,0),0),"")} | E42: {=IFERROR(INDEX(Kaisiadorys!Q:Q,MATCH(C42,Kaisiadorys!E:E,0),0),"")} -> 759 | F42: {=IFERROR(INDEX(Veisiejai!Q:Q,MATCH(C42,Veisiejai!E:E,0),0),"")} | G42: {=IFERROR(INDEX(Gdanskas!P:P,MATCH(C42,Gdanskas!C:C,0),0),"")} | H42: {=IFERROR(INDEX(Trakai!R:R,MATCH(C42,Trakai!E:E,0),0),"")} | I42: {=IFERROR(INDEX(Jonava!Q:Q,MATCH(C42,Jonava!E:E,0),0),"")} | J42: {=IFERROR(INDEX(Panevezys2!R:R,MATCH(C42,Panevezys2!E:E,0),0),"")} | K42: =IFERROR(INDEX(Skaudvile!Q:Q,MATCH(C42,Skaudvile!E:E,0),0),"") | L42: =IFERROR(INDEX(Moletai!Q:Q,MATCH(C42,Moletai!E:E,0),0),"") | N42: =COUNTIF(D42:M42,">0") -> 1 | O42: =SUM(D42:M42) -> 759 | P42: =O42/N42 -> 759 | Q42: {=IFERROR(SUMPRODUCT(LARGE(D42:M42,{1;2;3})),"0")} -> 0 | R42: =IFERROR(INDEX('Bendra įskaita (2025)'!A:A,MATCH(C42,'Bendra įskaita (2025)'!B:B,0),0),"") -> 15 | S42: =IFERROR(INDEX('Bendra įskaita (2025)'!K:K,MATCH(C42,'Bendra įskaita (2025)'!B:B,0),0),"") -> 3 | T42: =IFERROR(INDEX('Bendra įskaita (2024)'!A:A,MATCH(C42,'Bendra įskaita (2024)'!B:B,0),0),"") | U42: =IFERROR(INDEX('Bendra įskaita (2024)'!L:L,MATCH(C42,'Bendra įskaita (2024)'!B:B,0),0),"")
A43: 40 | B43: =Table_1[[#This Row],[2025 Vieta]]-A42 -> 12 | C43: Tomas Gruslys | D43: {=IFERROR(INDEX(Panevezys!P:P,MATCH(C43,Panevezys!E:E,0),0),"")} | E43: {=IFERROR(INDEX(Kaisiadorys!Q:Q,MATCH(C43,Kaisiadorys!E:E,0),0),"")} | F43: {=IFERROR(INDEX(Veisiejai!Q:Q,MATCH(C43,Veisiejai!E:E,0),0),"")} | G43: {=IFERROR(INDEX(Gdanskas!P:P,MATCH(C43,Gdanskas!C:C,0),0),"")} -> 758 | H43: {=IFERROR(INDEX(Trakai!R:R,MATCH(C43,Trakai!E:E,0),0),"")} -> 749 | I43: {=IFERROR(INDEX(Jonava!Q:Q,MATCH(C43,Jonava!E:E,0),0),"")} | J43: {=IFERROR(INDEX(Panevezys2!R:R,MATCH(C43,Panevezys2!E:E,0),0),"")} | K43: =IFERROR(INDEX(Skaudvile!Q:Q,MATCH(C43,Skaudvile!E:E,0),0),"") | L43: =IFERROR(INDEX(Moletai!Q:Q,MATCH(C43,Moletai!E:E,0),0),"") | N43: =COUNTIF(D43:M43,">0") -> 2 | O43: =SUM(D43:M43) -> 1507 | P43: =O43/N43 -> 753.5 | Q43: {=IFERROR(SUMPRODUCT(LARGE(D43:M43,{1;2;3})),"0")} -> 0 | R43: =IFERROR(INDEX('Bendra įskaita (2025)'!A:A,MATCH(C43,'Bendra įskaita (2025)'!B:B,0),0),"") -> 51 | S43: =IFERROR(INDEX('Bendra įskaita (2025)'!K:K,MATCH(C43,'Bendra įskaita (2025)'!B:B,0),0),"") -> 0 | T43: =IFERROR(INDEX('Bendra įskaita (2024)'!A:A,MATCH(C43,'Bendra įskaita (2024)'!B:B,0),0),"") -> 32 | U43: =IFERROR(INDEX('Bendra įskaita (2024)'!L:L,MATCH(C43,'Bendra įskaita (2024)'!B:B,0),0),"") -> 1
A44: 41 | B44: =Table_1[[#This Row],[2025 Vieta]]-A43 -> 0 | C44: Lina Alūzė | D44: {=IFERROR(INDEX(Panevezys!P:P,MATCH(C44,Panevezys!E:E,0),0),"")} | E44: {=IFERROR(INDEX(Kaisiadorys!Q:Q,MATCH(C44,Kaisiadorys!E:E,0),0),"")} -> 737 | F44: {=IFERROR(INDEX(Veisiejai!Q:Q,MATCH(C44,Veisiejai!E:E,0),0),"")} | G44: {=IFERROR(INDEX(Gdanskas!P:P,MATCH(C44,Gdanskas!C:C,0),0),"")} | H44: {=IFERROR(INDEX(Trakai!R:R,MATCH(C44,Trakai!E:E,0),0),"")} | I44: {=IFERROR(INDEX(Jonava!Q:Q,MATCH(C44,Jonava!E:E,0),0),"")} | J44: {=IFERROR(INDEX(Panevezys2!R:R,MATCH(C44,Panevezys2!E:E,0),0),"")} | K44: =IFERROR(INDEX(Skaudvile!Q:Q,MATCH(C44,Skaudvile!E:E,0),0),"") -> 740 | L44: =IFERROR(INDEX(Moletai!Q:Q,MATCH(C44,Moletai!E:E,0),0),"") | N44: =COUNTIF(D44:M44,">0") -> 2 | O44: =SUM(D44:M44) -> 1477 | P44: =O44/N44 -> 738.5 | Q44: {=IFERROR(SUMPRODUCT(LARGE(D44:M44,{1;2;3})),"0")} -> 0 | R44: =IFERROR(INDEX('Bendra įskaita (2025)'!A:A,MATCH(C44,'Bendra įskaita (2025)'!B:B,0),0),"") -> 40 | S44: =IFERROR(INDEX('Bendra įskaita (2025)'!K:K,MATCH(C44,'Bendra įskaita (2025)'!B:B,0),0),"") -> 1 | T44: =IFERROR(INDEX('Bendra įskaita (2024)'!A:A,MATCH(C44,'Bendra įskaita (2024)'!B:B,0),0),"") -> 76 | U44: =IFERROR(INDEX('Bendra įskaita (2024)'!L:L,MATCH(C44,'Bendra įskaita (2024)'!B:B,0),0),"") -> 0
...

Sheet Panevezys
A1: Pl. | B1: Bib | D1: Name | E1: Name Name | F1: Club | G1: Cat | H1: By cat. | I1: Plaukimas | J1: T1 | K1: Dviratis | L1: T2 | M1: Bėgimas | N1: Time | O1: Gap
A2: 1 | B2: 178 | C2: LTU | D2: JABLONSKIS Mantas | E2: Mantas JABLONSKIS | F2: TRItonas | G2: M30 | H2: 1 | I2: 0.0075925926 | J2: 0.00022106481 | K2: 0.019730324 | L2: 0.00036226852 | M2: 0.011717593 | N2: 0.039625 | P2: =IFERROR(ROUND($N$2/N2*900,0),0) -> 900
A3: 2 | B3: 218 | C3: LAT | D3: ŽIGARKOVS Sebastians | E3: Sebastians ŽIGARKOVS | F3: DTC Jaunība | G3: M20 | H3: 1 | I3: 0.0060763889 | J3: 0.00019212963 | K3: 0.021174769 | L3: 0.00020138889 | M3: 0.013392361 | N3: 0.041038194 | O3: +2:02.0 | P3: =IFERROR(ROUND($N$2/N3*900,0),0) -> 869
A4: 3 | B4: 195 | C4: LTU | D4: OGINTAS Andrius | E4: Andrius OGINTAS | F4: Klaipėdos triatlono klubas | G4: M40 | H4: 1 | I4: 0.0068402778 | J4: 0.00023032407 | K4: 0.020929398 | L4: 0.00026851852 | M4: 0.01346412 | N4: 0.041733796 | O4: +3:02.0 | P4: =IFERROR(ROUND($N$2/N4*900,0),0) -> 855
A5: 4 | B5: 165 | C5: LTU | D5: BARTKUS Mantas | E5: Mantas BARTKUS | F5: Kauno Triatlono Klubas | G5: M35 | H5: 1 | I5: 0.0075347222 | J5: 0.00022453704 | K5: 0.021701389 | L5: 0.00020601852 | M5: 0.012711806 | N5: 0.04237963 | O5: +3:58.0 | P5: =IFERROR(ROUND($N$2/N5*900,0),0) -> 842
A6: 5 | B6: 198 | C6: LTU | D6: PUMPUTIS Titas | E6: Titas PUMPUTIS | F6: Marijampolės triatlono draugija | G6: M25 | H6: 1 | I6: 0.0072453704 | J6: 0.0001724537 | K6: 0.021994213 | L6: 0.00020138889 | M6: 0.012997685 | N6: 0.042613426 | O6: +4:18.0 | P6: =IFERROR(ROUND($N$2/N6*900,0),0) -> 837
A7: 6 | B7: 217 | C7: LAT | D7: ŽIGARKOVS Viktors | E7: Viktors ŽIGARKOVS | F7: DTC Jaunība | G7: M45 | H7: 1 | I7: 0.0070717593 | J7: 0.00023148148 | K7: 0.022144676 | L7: 0.00030671296 | M7: 0.013186343 | N7: 0.042943287 | O7: +4:46.9 | P7: =IFERROR(ROUND($N$2/N7*900,0),0) -> 830
A8: 7 | B8: 190 | C8: LTU | D8: MARCINKEVIČIUS Mantas | E8: Mantas MARCINKEVIČIUS | F8: TRItonas | G8: M40 | H8: 2 | I8: 0.0078125 | J8: 0.00025347222 | K8: 0.021334491 | L8: 0.00024884259 | M8: 0.0134375 | N8: 0.043087963 | O8: +4:59.0 | P8: =IFERROR(ROUND($N$2/N8*900,0),0) -> 828
A9: 8 | B9: 179 | C9: LTU | D9: KAMINSKIJ Aleksej | E9: Aleksej KAMINSKIJ | F9: TRItonas | G9: M40 | H9: 3 | I9: 0.0081712963 | J9: 0.00023842593 | K9: 0.021020833 | L9: 0.00022569444 | M9: 0.013924769 | N9: 0.043582176 | O9: +5:41.9 | P9: =IFERROR(ROUND($N$2/N9*900,0),0) -> 818
A10: 9 | B10: 199 | C10: LTU | D10: REISAS Zigmas | E10: Zigmas REISAS | F10: BTT | G10: M20 | H10: 2 | I10: 0.0066898148 | J10: 0.00016898148 | K10: 0.021078704 | L10: 0.00020717593 | M10: 0.015746528 | N10: 0.043892361 | O10: +6:08.9 | P10: =IFERROR(ROUND($N$2/N10*900,0),0) -> 812
A11: 10 | B11: 166 | C11: LTU | D11: BELEŠKA Jonas | E11: +34:51.4 | F11: Kauno Triatlono Klubas | G11: M30 | H11: 2 | I11: 0.0067592593 | J11: 0.00020486111 | K11: 0.022717593 | L11: 0.00027430556 | M11: 0.014034722 | N11: 0.043993056 | O11: +6:17.9 | P11: =IFERROR(ROUND($N$2/N11*900,0),0) -> 811
A12: 11 | B12: 176 | C12: LTU | D12: GRIGAITIS Žilvinas | E12: Žilvinas GRIGAITIS | F12: Marijampolės triatlono draugija | G12: M35 | H12: 2 | I12: 0.006724537 | J12: 0.00021875 | K12: 0.022508102 | L12: 0.00023611111 | M12: 0.014398148 | N12: 0.044087963 | O12: +6:25.9 | P12: =IFERROR(ROUND($N$2/N12*900,0),0) -> 809
A13: 12 | B13: 181 | C13: LTU | D13: KAUPAS Kęstutis | E13: Kęstutis KAUPAS | G13: M40 | H13: 4 | I13: 0.008275463 | J13: 0.00024189815 | K13: 0.021418981 | L13: 0.00029976852 | M13: 0.013920139 | N13: 0.044157407 | O13: +6:31.9 | P13: =IFERROR(ROUND($N$2/N13*900,0),0) -> 808
A14: 13 | B14: 172 | C14: LTU | D14: GELŽINIS Artūras | E14: Artūras GELŽINIS | F14: Klaipėdos triatlono klubas | G14: M35 | H14: 3 | I14: 0.0084027778 | J14: 0.0002337963 | K14: 0.021260417 | L14: 0.00042939815 | M14: 0.013895833 | N14: 0.04422338 | O14: +6:37.0 | P14: =IFERROR(ROUND($N$2/N14*900,0),0) -> 806
A15: 14 | B15: 215 | C15: LTU | D15: VOLKOVICKI Julian | E15: Julian VOLKOVICKI | F15: zoomies | G15: M40 | H15: 5 | I15: 0.0078703704 | J15: 0.00021759259 | K15: 0.021346065 | L15: 0.00026851852 | M15: 0.014799769 | N15: 0.044503472 | O15: +7:01.9 | P15: =IFERROR(ROUND($N$2/N15*900,0),0) -> 801
A16: 15 | B16: 191 | C16: LTU | D16: MATULAITIS Lukas | E16: Lukas MATULAITIS | F16: TRItonas | G16: M35 | H16: 4 | I16: 0.0086921296 | J16: 0.00027083333 | K16: 0.022195602 | L16: 0.0003587963 | M16: 0.013480324 | N16: 0.045 | O16: +7:44.9 | P16: =IFERROR(ROUND($N$2/N16*900,0),0) -> 793
A17: 16 | B17: 205 | C17: LTU | D17: SRĖBALIUS Mantas | E17: Mantas SRĖBALIUS | G17: M30 | H17: 3 | I17: 0.0086921296 | J17: 0.00025231481 | K17: 0.022434028 | L17: 0.00038425926 | M17: 0.013774306 | N17: 0.045538194 | O17: +8:30.9 | P17: =IFERROR(ROUND($N$2/N17*900,0),0) -> 783
A18: 17 | B18: 192 | C18: LTU | D18: MICKUS Martynas | E18: Martynas MICKUS | F18: HighPeaks Lietuva | G18: M30 | H18: 4 | I18: 0.009212963 | J18: 0.00025115741 | K18: 0.021888889 | L18: 0.00036111111 | M18: 0.013912037 | N18: 0.045627315 | O18: +8:38.9 | P18: =IFERROR(ROUND($N$2/N18*900,0),0) -> 782
A19: 18 | B19: 180 | C19: LTU | D19: KATKUS Evaldas | E19: Evaldas KATKUS | F19: Love Streams Running | G19: M40 | H19: 6 | I19: 0.0094791667 | J19: 0.00034143519 | K19: 0.022149306 | L19: 0.00049652778 | M19: 0.013381944 | N19: 0.045849537 | O19: +8:57.9 | P19: =IFERROR(ROUND($N$2/N19*900,0),0) -> 778
A20: 19 | B20: 212 | C20: LTU | D20: URBONAS Pranas | E20: Pranas URBONAS | G20: M30 | H20: 5 | I20: 0.0087731481 | J20: 0.00023726852 | K20: 0.022425926 | L20: 0.00042708333 | M20: 0.014092593 | N20: 0.045957176 | O20: +9:07.0 | P20: =IFERROR(ROUND($N$2/N20*900,0),0) -> 776
A21: 20 | B21: 171 | C21: LTU | D21: GADRUS Eimantas | E21: Eimantas GADRUS | F21: HighPeaks Lietuva | G21: M30 | H21: 6 | I21: 0.0088888889 | J21: 0.00024537037 | K21: 0.022261574 | L21: 0.00045717593 | M21: 0.014266204 | N21: 0.04612037 | O21: +9:21.0 | P21: =IFERROR(ROUND($N$2/N21*900,0),0) -> 773
A22: 21 | B22: 173 | C22: LAT | D22: GLADIJS Nikita | E22: Nikita GLADIJS | F22: DTC Jaunība | G22: M20 | H22: 3 | I22: 0.0075578704 | J22: 0.00027314815 | K22: 0.023363426 | L22: 0.00062384259 | M22: 0.014512731 | N22: 0.046332176 | O22: +9:39.9 | P22: =IFERROR(ROUND($N$2/N22*900,0),0) -> 770
A23: 22 | B23: 211 | C23: LTU | D23: TURULIS Marius | E23: Marius TURULIS | G23: M45 | H23: 2 | I23: 0.0086111111 | J23: 0.00028009259 | K23: 0.022298611 | L23: 0.00040046296 | M23: 0.01478125 | N23: 0.046372685 | O23: +9:43.0 | P23: =IFERROR(ROUND($N$2/N23*900,0),0) -> 769
A24: 23 | B24: 208 | C24: LTU | D24: ŠIMKUS Darius | E24: Darius ŠIMKUS | F24: TriFamClub | G24: M35 | H24: 5 | I24: 0.0090625 | J24: 0.00021875 | K24: 0.02208912 | L24: 0.00031828704 | M24: 0.014778935 | N24: 0.04646875 | O24: +9:51.0 | P24: =IFERROR(ROUND($N$2/N24*900,0),0) -> 767
A25: 24 | B25: 204 | C25: LTU | D25: SIMANAITIS Povilas | E25: Povilas SIMANAITIS | F25: HighPeaks Lietuva | G25: M30 | H25: 7 | I25: 0.0089583333 | J25: 0.00023263889 | K25: 0.022149306 | L25: 0.00027546296 | M25: 0.015393519 | N25: 0.047011574 | O25: +10:38.0 | P25: =IFERROR(ROUND($N$2/N25*900,0),0) -> 759
A26: 25 | B26: 202 | C26: LTU | D26: SEREIČIKAS Arvydas | E26: Arvydas SEREIČIKAS | F26: TRItonas | G26: M40 | H26: 7 | I26: 0.0093865741 | J26: 0.00028240741 | K26: 0.022315972 | L26: 0.00049305556 | M26: 0.014572917 | N26: 0.047052083 | O26: +10:41.9 | P26: =IFERROR(ROUND($N$2/N26*900,0),0) -> 758
A27: 26 | B27: 187 | C27: LTU | D27: LYDIS Benas | E27: Benas LYDIS | F27: HighPeaks Lietuva | G27: M25 | H27: 2 | I27: 0.0089236111 | J27: 0.00028009259 | K27: 0.022770833 | L27: 0.00054050926 | M27: 0.01459838 | N27: 0.047114583 | O27: +10:47.0 | P27: =IFERROR(ROUND($N$2/N27*900,0),0) -> 757
A28: 27 | B28: 167 | C28: LTU | D28: BORISAS Darius | E28: Darius BORISAS | F28: TRItonas | G28: M35 | H28: 6 | I28: 0.0096180556 | J28: 0.00022106481 | K28: 0.022046296 | L28: 0.00038657407 | M28: 0.014920139 | N28: 0.047193287 | O28: +10:53.9 | P28: =IFERROR(ROUND($N$2/N28*900,0),0) -> 756
A29: 28 | B29: 194 | C29: LTU | D29: NAVICKAS Matas | E29: Matas NAVICKAS | F29: HighPeaks Lietuva | G29: M25 | H29: 3 | I29: 0.0088194444 | J29: 0.00024074074 | K29: 0.02265625 | L29: 0.00042592593 | M29: 0.015368056 | N29: 0.047511574 | O29: +11:21.9 | P29: =IFERROR(ROUND($N$2/N29*900,0),0) -> 751
A30: 29 | B30: 210 | C30: LTU | D30: TIJŪNONIS Darius | E30: Darius TIJŪNONIS | G30: M55 | H30: 1 | I30: 0.0093865741 | J30: 0.00029282407 | K30: 0.022327546 | L30: 0.00087962963 | M30: 0.015148148 | N30: 0.04803588 | O30: +12:06.9 | P30: =IFERROR(ROUND($N$2/N30*900,0),0) -> 742
A31: 30 | B31: 185 | C31: LTU | D31: KERZA Saulius | E31: Saulius KERZA | F31: TRItonas | G31: M50 | H31: 1 | I31: 0.0081944444 | J31: 0.00032523148 | K31: 0.023292824 | L31: 0.00042013889 | M31: 0.015810185 | N31: 0.048043981 | O31: +12:07.9 | P31: =IFERROR(ROUND($N$2/N31*900,0),0) -> 742
A32: 31 | B32: 174 | C32: LTU | D32: GRAŽINSKIS Domantas | E32: Domantas GRAŽINSKIS | F32: Marijampolės triatlono draugija | G32: M25 | H32: 4 | I32: 0.0097337963 | J32: 0.00026736111 | K32: 0.023336806 | L32: 0.00049074074 | M32: 0.014931713 | N32: 0.048762731 | O32: +13:09.9 | P32: =IFERROR(ROUND($N$2/N32*900,0),0) -> 731
A33: 32 | B33: 200 | C33: LTU | D33: SAKALAUSKAS Mantas | E33: Mantas SAKALAUSKAS | F33: HighPeaks Lietuva | G33: M35 | H33: 7 | I33: 0.0084722222 | J33: 0.00028819444 | K33: 0.024572917 | L33: 0.00046643519 | M33: 0.015355324 | N33: 0.049158565 | O33: +13:43.9 | P33: =IFERROR(ROUND($N$2/N33*900,0),0) -> 725
A34: 33 | B34: 163 | C34: LTU | D34: BALČIŪNAS Ovidijus | E34: +44:11.6 | F34: S-Sportas | G34: M30 | H34: 8 | I34: 0.011388889 | J34: 0.00028009259 | K34: 0.023912037 | L34: 0.00042592593 | M34: 0.013217593 | N34: 0.049225694 | O34: +13:49.9 | P34: =IFERROR(ROUND($N$2/N34*900,0),0) -> 724
A35: 34 | B35: 216 | C35: LTU | D35: VRUBLIAUSKAS Modestas | E35: Modestas VRUBLIAUSKAS | F35: HighPeaks Lietuva | G35: M30 | H35: 9 | I35: 0.010451389 | J35: 0.00025694444 | K35: 0.0231875 | L35: 0.00037384259 | M35: 0.015165509 | N35: 0.0494375 | O35: +14:07.9 | P35: =IFERROR(ROUND($N$2/N35*900,0),0) -> 721
A36: 35 | B36: 169 | C36: LTU | D36: DARIUS Biržietis | E36: Biržietis DARIUS | F36: Individualiai | G36: M55 | H36: 2 | I36: 0.010011574 | J36: 0.0003125 | K36: 0.024359954 | L36: 0.00046643519 | M36: 0.014568287 | N36: 0.049719907 | O36: +14:32.0 | P36: =IFERROR(ROUND($N$2/N36*900,0),0) -> 717
